Workbook

Sheet DATA
A2: ASSET REF | B2: ASSET NAME | C2: PO NUMBER | D2: ACC REF | E2: CONTRACTOR / CONSULTANTS | F2: INITIAL | G2: CONTRACTOR / CONSULTANT / DIRECT ACTUAL | H2: PACKAGE | I2: CODE 1 | J2: CODE 2 | K2: CODE 3 | L2: CODE 4 | M2: ACC 1 | N2: ACC 2 | O2: ACC 3
A3: 1.TB.01.003.01 | B3: AMAALAYachtClub | C3: 2210224 | D3: 003C13 | E3: Soil Improvement Contracting | F3: SOIL IMPROVE | G3: Contractor | H3: Triple Bay Wide Ground Improvement | I3: CN | J3: =RIGHT(A3,2) -> 01 | K3: =I3&"."&D3 -> CN.003C13 | L3: =E3&" - "&C3 -> Soil Improvement Contracting - 2210224 | M3: ="1TB01006"&"."&J3&"."&I3&"."&D3&".00" -> 1TB01006.01.CN.003C13.00 | N3: ="1TB01006"&"."&J3&"."&I3&"."&D3&".01" -> 1TB01006.01.CN.003C13.01 | O3: ="1TB01006"&"."&J3&"."&I3&"."&D3&".02" -> 1TB01006.01.CN.003C13.02
A4: 1.TB.01.003.01 | B4: AMAALAYachtClub | C4: 2210167 | D4: 003D04 | E4: Applied Technology and Management Inc (Dubai BR) | F4: APPLIED TECH | G4: Consultant | H4: Rapid Peer Review of AMAALA Existing Design of Yachting and Marina Facilities | I4: PS | J4: =RIGHT(A4,2) -> 01 | K4: =I4&"."&D4 -> PS.003D04 | L4: =E4&" - "&C4 -> Applied Technology and Management Inc (Dubai BR) - 2210167 | M4: ="1TB01006"&"."&J4&"."&I4&"."&D4&".00" -> 1TB01006.01.PS.003D04.00 | N4: ="1TB01006"&"."&J4&"."&I4&"."&D4&".01" -> 1TB01006.01.PS.003D04.01 | O4: ="1TB01006"&"."&J4&"."&I4&"."&D4&".02" -> 1TB01006.01.PS.003D04.02
A5: 1.TB.01.003.01 | B5: AMAALAYachtClub | C5: 2200445 | D5: 003D01 | E5: Dewan Architects & Engineers | F5: DEWAN | G5: Consultant | H5: Triple Bay Hijaz Yacht Club - Lead Consultant Services | I5: PS | J5: =RIGHT(A5,2) -> 01 | K5: =I5&"."&D5 -> PS.003D01 | L5: =E5&" - "&C5 -> Dewan Architects & Engineers - 2200445 | M5: ="1TB01006"&"."&J5&"."&I5&"."&D5&".00" -> 1TB01006.01.PS.003D01.00 | N5: ="1TB01006"&"."&J5&"."&I5&"."&D5&".01" -> 1TB01006.01.PS.003D01.01 | O5: ="1TB01006"&"."&J5&"."&I5&"."&D5&".02" -> 1TB01006.01.PS.003D01.02
A6: 1.TB.01.003.01 | B6: AMAALAYachtClub | C6: 2200375 | D6: 003D03 | E6: HKS Architects Limited | F6: HKS | G6: Consultant | H6: Triple Bay Marine Yacht Club - Design Architect Consultancy Services | I6: PS | J6: =RIGHT(A6,2) -> 01 | K6: =I6&"."&D6 -> PS.003D03 | L6: =E6&" - "&C6 -> HKS Architects Limited - 2200375 | M6: ="1TB01006"&"."&J6&"."&I6&"."&D6&".00" -> 1TB01006.01.PS.003D03.00 | N6: ="1TB01006"&"."&J6&"."&I6&"."&D6&".01" -> 1TB01006.01.PS.003D03.01 | O6: ="1TB01006"&"."&J6&"."&I6&"."&D6&".02" -> 1TB01006.01.PS.003D03.02
A7: 1.TB.01.003.01 | B7: AMAALAYachtClub | C7: 2200010 | D7: 003D02 | E7: HKS Architects Limited | F7: HKS | G7: Consultant | H7: Design Competition | I7: PS | J7: =RIGHT(A7,2) -> 01 | K7: =I7&"."&D7 -> PS.003D02 | L7: =E7&" - "&C7 -> HKS Architects Limited - 2200010 | M7: ="1TB01006"&"."&J7&"."&I7&"."&D7&".00" -> 1TB01006.01.PS.003D02.00 | N7: ="1TB01006"&"."&J7&"."&I7&"."&D7&".01" -> 1TB01006.01.PS.003D02.01 | O7: ="1TB01006"&"."&J7&"."&I7&"."&D7&".02" -> 1TB01006.01.PS.003D02.02
A8: 1.TB.01.003.01 | B8: AMAALAYachtClub | C8: 2220032 | D8: 003C14 | E8: NSCC International Saudi Contracting | F8: NSCC | G8: Contractor | H8: Triple Bay Piling - Beach, RSMLI, Yacht Club and Marina Village Precinct (Hotel 1 and 2) | I8: CN | J8: =RIGHT(A8,2) -> 01 | K8: =I8&"."&D8 -> CN.003C14 | L8: =E8&" - "&C8 -> NSCC International Saudi Contracting - 2220032 | M8: ="1TB01006"&"."&J8&"."&I8&"."&D8&".00" -> 1TB01006.01.CN.003C14.00 | N8: ="1TB01006"&"."&J8&"."&I8&"."&D8&".01" -> 1TB01006.01.CN.003C14.01 | O8: ="1TB01006"&"."&J8&"."&I8&"."&D8&".02" -> 1TB01006.01.CN.003C14.02
A9: 1.TB.01.003.01 | B9: AMAALAYachtClub | C9: 2220038 | D9: 003C20 | E9: Green Business Certification Inc | F9: GREEN BUSSINESS | G9: Direct Actuals | H9: Sustainability Accreditation, third party technical reviews and verification of LEED-registered AMAALA Projects | I9: CN | J9: =RIGHT(A9,2) -> 01 | K9: =I9&"."&D9 -> CN.003C20 | L9: =E9&" - "&C9 -> Green Business Certification Inc - 2220038 | M9: ="1TB01006"&"."&J9&"."&I9&"."&D9&".00" -> 1TB01006.01.CN.003C20.00 | N9: ="1TB01006"&"."&J9&"."&I9&"."&D9&".01" -> 1TB01006.01.CN.003C20.01 | O9: ="1TB01006"&"."&J9&"."&I9&"."&D9&".02" -> 1TB01006.01.CN.003C20.02
A10: 1.TB.01.003.01 | B10: AMAALAYachtClub | C10: 2230023 | D10: 003C03 | E10: Saudi Arabian Baytur Construction Company | F10: BAYTUR | G10: Contractor | H10: Construction Contract - Site Enabling, Civil Works, Structural Concrete, Structural Steel, BOH Finishes, Building Envelope, MEP Including Tertiary Infrastructure & ICT/ELV | I10: CN | J10: =RIGHT(A10,2) -> 01 | K10: =I10&"."&D10 -> CN.003C03 | L10: =E10&" - "&C10 -> Saudi Arabian Baytur Construction Company - 2230023 | M10: ="1TB01006"&"."&J10&"."&I10&"."&D10&".00" -> 1TB01006.01.CN.003C03.00 | N10: ="1TB01006"&"."&J10&"."&I10&"."&D10&".01" -> 1TB01006.01.CN.003C03.01 | O10: ="1TB01006"&"."&J10&"."&I10&"."&D10&".02" -> 1TB01006.01.CN.003C03.02
A11: 1.TB.01.003.01 | B11: AMAALAYachtClub | C11: 2230042 | D11: 003D05 | E11: LANGAN International UK, LTD | F11: LANGAN INNTERNATIONAL | G11: Consultant | H11: Geotechnical Consultancy Services (Yacht Club) - Peer Review | I11: PS | J11: =RIGHT(A11,2) -> 01 | K11: =I11&"."&D11 -> PS.003D05 | L11: =E11&" - "&C11 -> LANGAN International UK, LTD - 2230042 | M11: ="1TB01006"&"."&J11&"."&I11&"."&D11&".00" -> 1TB01006.01.PS.003D05.00 | N11: ="1TB01006"&"."&J11&"."&I11&"."&D11&".01" -> 1TB01006.01.PS.003D05.01 | O11: ="1TB01006"&"."&J11&"."&I11&"."&D11&".02" -> 1TB01006.01.PS.003D05.02
A12: 1.TB.01.003.01 | B12: AMAALAYachtClub | C12: 2230075 | D12: 003C21 | E12: Medtel - W.N | F12: MEDTEL | G12: Contractor | H12: Sto Façade Mock-Up | I12: CN | J12: =RIGHT(A12,2) -> 01 | K12: =I12&"."&D12 -> CN.003C21 | L12: =E12&" - "&C12 -> Medtel - W.N - 2230075 | M12: ="1TB01006"&"."&J12&"."&I12&"."&D12&".00" -> 1TB01006.01.CN.003C21.00 | N12: ="1TB01006"&"."&J12&"."&I12&"."&D12&".01" -> 1TB01006.01.CN.003C21.01 | O12: ="1TB01006"&"."&J12&"."&I12&"."&D12&".02" -> 1TB01006.01.CN.003C21.02
A13: 1.TB.01.003.01 | B13: AMAALAYachtClub | C13: 2230031 | D13: 003F02 | E13: Saudi Consolidated Engineering Company - Khatib & Alami | F13: KHATIB & ALAMI | G13: Consultant | H13: Construction Supervision Services - AMAALA Yacht Club (Call off Order No: 003) | I13: MS | J13: =RIGHT(A13,2) -> 01 | K13: =I13&"."&D13 -> MS.003F02 | L13: =E13&" - "&C13 -> Saudi Consolidated Engineering Company - Khatib & Alami - 2230031 | M13: ="1TB01006"&"."&J13&"."&I13&"."&D13&".00" -> 1TB01006.01.MS.003F02.00 | N13: ="1TB01006"&"."&J13&"."&I13&"."&D13&".01" -> 1TB01006.01.MS.003F02.01 | O13: ="1TB01006"&"."&J13&"."&I13&"."&D13&".02" -> 1TB01006.01.MS.003F02.02
A14: 1.TB.01.003.01 | B14: AMAALAYachtClub | C14: 699226 | D14: 003D06 | E14: Ministry of Municipality and Rural Affairs | F14: MINISTRY | G14: Direct Actuals | H14: Permit Fees | I14: PS | J14: =RIGHT(A14,2) -> 01 | K14: =I14&"."&D14 -> PS.003D06 | L14: =E14&" - "&C14 -> Ministry of Municipality and Rural Affairs - 699226 | M14: ="1TB01006"&"."&J14&"."&I14&"."&D14&".00" -> 1TB01006.01.PS.003D06.00 | N14: ="1TB01006"&"."&J14&"."&I14&"."&D14&".01" -> 1TB01006.01.PS.003D06.01 | O14: ="1TB01006"&"."&J14&"."&I14&"."&D14&".02" -> 1TB01006.01.PS.003D06.02
... A31: 1.TB.01.003.01 | B31: AMAALAYachtClub | C31: 2250145 | D31: 003C37 | E31: Hassan Allam Construction Saudi Limited | F31: HASSAN ALLAM | G31: Contractor | H31: Scaffolding Services | I31: CN | J31: =RIGHT(A31,2) -> 01 | K31: =I31&"."&D31 -> CN.003C37 | L31: =E31&" - "&C31 -> Hassan Allam Construction Saudi Limited - 2250145 | M31: ="1TB01006"&"."&J31&"."&I31&"."&D31&".00" -> 1TB01006.01.CN.003C37.00 | N31: ="1TB01006"&"."&J31&"."&I31&"."&D31&".01" -> 1TB01006.01.CN.003C37.01 | O31: ="1TB01006"&"."&J31&"."&I31&"."&D31&".02" -> 1TB01006.01.CN.003C37.02
A32: 1.TB.01.003.01 | B32: AMAALAYachtClub | C32: BAYTUR_PAYMENT | D32: 003C66 | E32: Sami General Contracting Est. | F32: SAMI GENEERAL | G32: Contractor | H32: Payment On Behalf Of Saudi Arabian Baytur (Jan/Feb) | I32: CN | J32: =RIGHT(A32,2) -> 01 | K32: =I32&"."&D32 -> CN.003C66 | L32: =E32&" - "&C32 -> Sami General Contracting Est. - BAYTUR_PAYMENT | M32: ="1TB01006"&"."&J32&"."&I32&"."&D32&".00" -> 1TB01006.01.CN.003C66.00 | N32: ="1TB01006"&"."&J32&"."&I32&"."&D32&".01" -> 1TB01006.01.CN.003C66.01 | O32: ="1TB01006"&"."&J32&"."&I32&"."&D32&".02" -> 1TB01006.01.CN.003C66.02
A33: 1.TB.01.003.01 | B33: AMAALAYachtClub | C33: BAYTUR_PAYMENT | D33: 003C42 | E33: Saad Al Easa - Metal Industry | F33: SAAD | G33: Contractor | H33: Payment On Behalf Of Saudi Arabian Baytur (Jan/Feb) | I33: CN | J33: =RIGHT(A33,2) -> 01 | K33: =I33&"."&D33 -> CN.003C42 | L33: =E33&" - "&C33 -> Saad Al Easa - Metal Industry - BAYTUR_PAYMENT | M33: ="1TB01006"&"."&J33&"."&I33&"."&D33&".00" -> 1TB01006.01.CN.003C42.00 | N33: ="1TB01006"&"."&J33&"."&I33&"."&D33&".01" -> 1TB01006.01.CN.003C42.01 | O33: ="1TB01006"&"."&J33&"."&I33&"."&D33&".02" -> 1TB01006.01.CN.003C42.02
A34: 1.TB.01.003.01 | B34: AMAALAYachtClub | C34: BAYTUR_PAYMENT | D34: 003C70 | E34: Aldrees Petroleum and Transport Services Company | F34: ALDREES | G34: Contractor | H34: Payment On Behalf Of Saudi Arabian Baytur (Jan/Feb) | I34: CN | J34: =RIGHT(A34,2) -> 01 | K34: =I34&"."&D34 -> CN.003C70 | L34: =E34&" - "&C34 -> Aldrees Petroleum and Transport Services Company - BAYTUR_PAYMENT | M34: ="1TB01006"&"."&J34&"."&I34&"."&D34&".00" -> 1TB01006.01.CN.003C70.00 | N34: ="1TB01006"&"."&J34&"."&I34&"."&D34&".01" -> 1TB01006.01.CN.003C70.01 | O34: ="1TB01006"&"."&J34&"."&I34&"."&D34&".02" -> 1TB01006.01.CN.003C70.02
A35: 1.TB.01.003.01 | B35: AMAALAYachtClub | C35: BAYTUR_PAYMENT | D35: 003C69 | E35: Salim Hamed Cleaning | F35: SALIM | G35: Contractor | H35: Payment On Behalf Of Saudi Arabian Baytur (Jan/Feb) | I35: CN | J35: =RIGHT(A35,2) -> 01 | K35: =I35&"."&D35 -> CN.003C69 | L35: =E35&" - "&C35 -> Salim Hamed Cleaning - BAYTUR_PAYMENT | M35: ="1TB01006"&"."&J35&"."&I35&"."&D35&".00" -> 1TB01006.01.CN.003C69.00 | N35: ="1TB01006"&"."&J35&"."&I35&"."&D35&".01" -> 1TB01006.01.CN.003C69.01 | O35: ="1TB01006"&"."&J35&"."&I35&"."&D35&".02" -> 1TB01006.01.CN.003C69.02
A36: 1.TB.01.003.01 | B36: AMAALAYachtClub | C36: BAYTUR_PAYMENT | D36: 003C65 | E36: Eastern Horizon Foundation Transportation Comp. | F36: EASTERN | G36: Contractor | H36: Payment On Behalf Of Saudi Arabian Baytur (Jan/Feb) | I36: CN | J36: =RIGHT(A36,2) -> 01 | K36: =I36&"."&D36 -> CN.003C65 | L36: =E36&" - "&C36 -> Eastern Horizon Foundation Transportation Comp. - BAYTUR_PAYMENT | M36: ="1TB01006"&"."&J36&"."&I36&"."&D36&".00" -> 1TB01006.01.CN.003C65.00 | N36: ="1TB01006"&"."&J36&"."&I36&"."&D36&".01" -> 1TB01006.01.CN.003C65.01 | O36: ="1TB01006"&"."&J36&"."&I36&"."&D36&".02" -> 1TB01006.01.CN.003C65.02
A37: 1.TB.01.003.01 | B37: AMAALAYachtClub | C37: BAYTUR_PAYMENT | D37: 003C64 | E37: JAK Generation Cont. Co. LLC | F37: JAK | G37: Contractor | H37: Payment On Behalf Of Saudi Arabian Baytur (Jan/Feb) | I37: CN | J37: =RIGHT(A37,2) -> 01 | K37: =I37&"."&D37 -> CN.003C64 | L37: =E37&" - "&C37 -> JAK Generation Cont. Co. LLC - BAYTUR_PAYMENT | M37: ="1TB01006"&"."&J37&"."&I37&"."&D37&".00" -> 1TB01006.01.CN.003C64.00 | N37: ="1TB01006"&"."&J37&"."&I37&"."&D37&".01" -> 1TB01006.01.CN.003C64.01 | O37: ="1TB01006"&"."&J37&"."&I37&"."&D37&".02" -> 1TB01006.01.CN.003C64.02
A38: 1.TB.01.003.01 | B38: AMAALAYachtClub | C38: BAYTUR_PAYMENT | D38: 003C67 | E38: Clean Coast For Contracting | F38: CLEAN COAST | G38: Contractor | H38: Payment On Behalf Of Saudi Arabian Baytur (Jan/Feb) | I38: CN | J38: =RIGHT(A38,2) -> 01 | K38: =I38&"."&D38 -> CN.003C67 | L38: =E38&" - "&C38 -> Clean Coast For Contracting - BAYTUR_PAYMENT | M38: ="1TB01006"&"."&J38&"."&I38&"."&D38&".00" -> 1TB01006.01.CN.003C67.00 | N38: ="1TB01006"&"."&J38&"."&I38&"."&D38&".01" -> 1TB01006.01.CN.003C67.01 | O38: ="1TB01006"&"."&J38&"."&I38&"."&D38&".02" -> 1TB01006.01.CN.003C67.02
A39: 1.TB.01.003.01 | B39: AMAALAYachtClub | C39: BAYTUR_PAYMENT | D39: 003C61 | E39: Al Rai Modern Water Factory | F39: AL RAI | G39: Contractor | H39: Payment On Behalf Of Saudi Arabian Baytur (Jan/Feb) | I39: CN | J39: =RIGHT(A39,2) -> 01 | K39: =I39&"."&D39 -> CN.003C61 | L39: =E39&" - "&C39 -> Al Rai Modern Water Factory - BAYTUR_PAYMENT | M39: ="1TB01006"&"."&J39&"."&I39&"."&D39&".00" -> 1TB01006.01.CN.003C61.00 | N39: ="1TB01006"&"."&J39&"."&I39&"."&D39&".01" -> 1TB01006.01.CN.003C61.01 | O39: ="1TB01006"&"."&J39&"."&I39&"."&D39&".02" -> 1TB01006.01.CN.003C61.02
A40: 1.TB.01.003.01 | B40: AMAALAYachtClub | C40: BAYTUR_PAYMENT | D40: 003C57 | E40: Juffali Technical Equipment Company | F40: JUFFALI TTECHNICAL | G40: Contractor | H40: Payment On Behalf Of Saudi Arabian Baytur (Jan/Feb) | I40: CN | J40: =RIGHT(A40,2) -> 01 | K40: =I40&"."&D40 -> CN.003C57 | L40: =E40&" - "&C40 -> Juffali Technical Equipment Company - BAYTUR_PAYMENT | M40: ="1TB01006"&"."&J40&"."&I40&"."&D40&".00" -> 1TB01006.01.CN.003C57.00 | N40: ="1TB01006"&"."&J40&"."&I40&"."&D40&".01" -> 1TB01006.01.CN.003C57.01 | O40: ="1TB01006"&"."&J40&"."&I40&"."&D40&".02" -> 1TB01006.01.CN.003C57.02
A41: 1.TB.01.003.01 | B41: AMAALAYachtClub | C41: BAYTUR_PAYMENT | D41: 003C63 | E41: Intelligent General Cont. Co - Equipment - Industrial Forklift & 5ton | F41: INTELLIGENT | G41: Contractor | H41: Payment On Behalf Of Saudi Arabian Baytur (Jan/Feb) | I41: CN | J41: =RIGHT(A41,2) -> 01 | K41: =I41&"."&D41 -> CN.003C63 | L41: =E41&" - "&C41 -> Intelligent General Cont. Co - Equipment - Industrial Forklift & 5ton - BAYTUR_PAYMENT | M41: ="1TB01006"&"."&J41&"."&I41&"."&D41&".00" -> 1TB01006.01.CN.003C63.00 | N41: ="1TB01006"&"."&J41&"."&I41&"."&D41&".01" -> 1TB01006.01.CN.003C63.01 | O41: ="1TB01006"&"."&J41&"."&I41&"."&D41&".02" -> 1TB01006.01.CN.003C63.02
A42: 1.TB.01.003.01 | B42: AMAALAYachtClub | C42: BAYTUR_PAYMENT | D42: 003C71 | E42: Al-Anan Travels and Tours | F42: AL ANAN | G42: Contractor | H42: Payment On Behalf Of Saudi Arabian Baytur (Jan/Feb) | I42: CN | J42: =RIGHT(A42,2) -> 01 | K42: =I42&"."&D42 -> CN.003C71 | L42: =E42&" - "&C42 -> Al-Anan Travels and Tours - BAYTUR_PAYMENT | M42: ="1TB01006"&"."&J42&"."&I42&"."&D42&".00" -> 1TB01006.01.CN.003C71.00 | N42: ="1TB01006"&"."&J42&"."&I42&"."&D42&".01" -> 1TB01006.01.CN.003C71.01 | O42: ="1TB01006"&"."&J42&"."&I42&"."&D42&".02" -> 1TB01006.01.CN.003C71.02
A43: 1.TB.01.003.01 | B43: AMAALAYachtClub | C43: BAYTUR_PAYMENT | D43: 003C58 | E43: Madar Building Material Co. | F43: MADAR BUIILDING | G43: Contractor | H43: Payment On Behalf Of Saudi Arabian Baytur (Jan/Feb) | I43: CN | J43: =RIGHT(A43,2) -> 01 | K43: =I43&"."&D43 -> CN.003C58 | L43: =E43&" - "&C43 -> Madar Building Material Co. - BAYTUR_PAYMENT | M43: ="1TB01006"&"."&J43&"."&I43&"."&D43&".00" -> 1TB01006.01.CN.003C58.00 | N43: ="1TB01006"&"."&J43&"."&I43&"."&D43&".01" -> 1TB01006.01.CN.003C58.01 | O43: ="1TB01006"&"."&J43&"."&I43&"."&D43&".02" -> 1TB01006.01.CN.003C58.02
... A90: 1.TB.01.003.01 | B90: AMAALAYachtClub | C90: BAYTUR_PAYMENT | D90: 003C79 | E90: Glsan Contracting Company | F90: GLSAN | G90: Contractor | H90: Payment On Behalf Of Saudi Arabian Baytur (Mar) | I90: CN | J90: =RIGHT(A90,2) -> 01 | K90: =I90&"."&D90 -> CN.003C79 | L90: =E90&" - "&C90 -> Glsan Contracting Company - BAYTUR_PAYMENT | M90: ="1TB01006"&"."&J90&"."&I90&"."&D90&".00" -> 1TB01006.01.CN.003C79.00 | N90: ="1TB01006"&"."&J90&"."&I90&"."&D90&".01" -> 1TB01006.01.CN.003C79.01 | O90: ="1TB01006"&"."&J90&"."&I90&"."&D90&".02" -> 1TB01006.01.CN.003C79.02
A91: 1.TB.01.003.01 | B91: AMAALAYachtClub | C91: 2250184 | D91: 003F10 | E91: Jensen Hughes Saudi Arabia, LLC | F91: JENSEN | G91: Consultant | H91: Third-Party Authority for Fire and Life Safety Review & Certification Endorsement (Call off Order No: 031) | I91: PS | J91: =RIGHT(A91,2) -> 01 | K91: =I91&"."&D91 -> PS.003F10 | L91: =E91&" - "&C91 -> Jensen Hughes Saudi Arabia, LLC - 2250184 | M91: ="1TB01006"&"."&J91&"."&I91&"."&D91&".00" -> 1TB01006.01.PS.003F10.00 | N91: ="1TB01006"&"."&J91&"."&I91&"."&D91&".01" -> 1TB01006.01.PS.003F10.01 | O91: ="1TB01006"&"."&J91&"."&I91&"."&D91&".02" -> 1TB01006.01.PS.003F10.02
A92: 1.TB.01.003.01 | B92: AMAALAYachtClub | C92: BAYTUR_PAYMENT | D92: 003C81 | E92: Jameel Mohammed Hussain Alqatafa Cont.Est. | F92: JAMEEL | G92: Contractor | H92: Payment On Behalf Of Saudi Arabian Baytur (Mar) | I92: CN | J92: =RIGHT(A92,2) -> 01 | K92: =I92&"."&D92 -> CN.003C81 | L92: =E92&" - "&C92 -> Jameel Mohammed Hussain Alqatafa Cont.Est. - BAYTUR_PAYMENT | M92: ="1TB01006"&"."&J92&"."&I92&"."&D92&".00" -> 1TB01006.01.CN.003C81.00 | N92: ="1TB01006"&"."&J92&"."&I92&"."&D92&".01" -> 1TB01006.01.CN.003C81.01 | O92: ="1TB01006"&"."&J92&"."&I92&"."&D92&".02" -> 1TB01006.01.CN.003C81.02
A93: 1.TB.01.003.01 | B93: AMAALAYachtClub | C93: BAYTUR_PAYMENT | D93: 003C89 | E93: Issam Kabani and Partners | F93: ISSAM KABBANI | G93: Contractor | H93: Payment On Behalf Of Saudi Arabian Baytur (Mar) | I93: CN | J93: =RIGHT(A93,2) -> 01 | K93: =I93&"."&D93 -> CN.003C89 | L93: =E93&" - "&C93 -> Issam Kabani and Partners - BAYTUR_PAYMENT | M93: ="1TB01006"&"."&J93&"."&I93&"."&D93&".00" -> 1TB01006.01.CN.003C89.00 | N93: ="1TB01006"&"."&J93&"."&I93&"."&D93&".01" -> 1TB01006.01.CN.003C89.01 | O93: ="1TB01006"&"."&J93&"."&I93&"."&D93&".02" -> 1TB01006.01.CN.003C89.02
A94: 1.TB.01.003.01 | B94: AMAALAYachtClub | C94: BAYTUR_PAYMENT | D94: 003C90 | E94: Saad Al Easa - Metal Industry | F94: SAAD | G94: Contractor | H94: Payment On Behalf Of Saudi Arabian Baytur (Mar) | I94: CN | J94: =RIGHT(A94,2) -> 01 | K94: =I94&"."&D94 -> CN.003C90 | L94: =E94&" - "&C94 -> Saad Al Easa - Metal Industry - BAYTUR_PAYMENT | M94: ="1TB01006"&"."&J94&"."&I94&"."&D94&".00" -> 1TB01006.01.CN.003C90.00 | N94: ="1TB01006"&"."&J94&"."&I94&"."&D94&".01" -> 1TB01006.01.CN.003C90.01 | O94: ="1TB01006"&"."&J94&"."&I94&"."&D94&".02" -> 1TB01006.01.CN.003C90.02
A95: 1.TB.01.003.01 | B95: AMAALAYachtClub | C95: BAYTUR_PAYMENT | D95: 003C91 | E95: Medtel - W.N | F95: MEDTEL | G95: Contractor | H95: Payment On Behalf Of Saudi Arabian Baytur (Mar) | I95: CN | J95: =RIGHT(A95,2) -> 01 | K95: =I95&"."&D95 -> CN.003C91 | L95: =E95&" - "&C95 -> Medtel - W.N - BAYTUR_PAYMENT | M95: ="1TB01006"&"."&J95&"."&I95&"."&D95&".00" -> 1TB01006.01.CN.003C91.00 | N95: ="1TB01006"&"."&J95&"."&I95&"."&D95&".01" -> 1TB01006.01.CN.003C91.01 | O95: ="1TB01006"&"."&J95&"."&I95&"."&D95&".02" -> 1TB01006.01.CN.003C91.02
A96: 1.TB.01.003.01 | B96: AMAALAYachtClub | C96: BAYTUR_PAYMENT | D96: 003C82 | E96: Gesr Alarab | F96: GESR | G96: Contractor | H96: Payment On Behalf Of Saudi Arabian Baytur (Mar) | I96: CN | J96: =RIGHT(A96,2) -> 01 | K96: =I96&"."&D96 -> CN.003C82 | L96: =E96&" - "&C96 -> Gesr Alarab - BAYTUR_PAYMENT | M96: ="1TB01006"&"."&J96&"."&I96&"."&D96&".00" -> 1TB01006.01.CN.003C82.00 | N96: ="1TB01006"&"."&J96&"."&I96&"."&D96&".01" -> 1TB01006.01.CN.003C82.01 | O96: ="1TB01006"&"."&J96&"."&I96&"."&D96&".02" -> 1TB01006.01.CN.003C82.02
A97: 1.TB.01.003.01 | B97: AMAALAYachtClub | C97: BAYTUR_PAYMENT | D97: 003C80 | E97: Glsan Contracting Company | F97: GLSAN | G97: Contractor | H97: Payment On Behalf Of Saudi Arabian Baytur (Mar) | I97: CN | J97: =RIGHT(A97,2) -> 01 | K97: =I97&"."&D97 -> CN.003C80 | L97: =E97&" - "&C97 -> Glsan Contracting Company - BAYTUR_PAYMENT | M97: ="1TB01006"&"."&J97&"."&I97&"."&D97&".00" -> 1TB01006.01.CN.003C80.00 | N97: ="1TB01006"&"."&J97&"."&I97&"."&D97&".01" -> 1TB01006.01.CN.003C80.01 | O97: ="1TB01006"&"."&J97&"."&I97&"."&D97&".02" -> 1TB01006.01.CN.003C80.02
A98: 1.TB.01.003.01 | B98: AMAALAYachtClub | C98: N/A | D98: 003CXX | E98: Ahmed Bin Salem Bin Dagher Al-Balawi Est. | F98: AHMED BIN SALEM | G98: Contractor | H98: Payment On Behalf Of Saudi Arabian Baytur (Mar)_CONTRACT CANCELLED_CONTRACT VALUE SAR 22,058.81 | I98: CN | J98: =RIGHT(A98,2) -> 01 | K98: =I98&"."&D98 -> CN.003CXX | L98: =E98&" - "&C98 -> Ahmed Bin Salem Bin Dagher Al-Balawi Est. - N/A | M98: ="1TB01006"&"."&J98&"."&I98&"."&D98&".00" -> 1TB01006.01.CN.003CXX.00 | N98: ="1TB01006"&"."&J98&"."&I98&"."&D98&".01" -> 1TB01006.01.CN.003CXX.01 | O98: ="1TB01006"&"."&J98&"."&I98&"."&D98&".02" -> 1TB01006.01.CN.003CXX.02
A99: 1.TB.01.003.01 | B99: AMAALAYachtClub | C99: BAYTUR_PAYMENT | D99: 003C149 | E99: Clean Coast For Contracting | F99: CLEAN COAST | G99: Contractor | H99: Payment On Behalf Of Saudi Arabian Baytur (Mar) | I99: CN | J99: =RIGHT(A99,2) -> 01 | K99: =I99&"."&D99 -> CN.003C149 | L99: =E99&" - "&C99 -> Clean Coast For Contracting - BAYTUR_PAYMENT | M99: ="1TB01006"&"."&J99&"."&I99&"."&D99&".00" -> 1TB01006.01.CN.003C149.00 | N99: ="1TB01006"&"."&J99&"."&I99&"."&D99&".01" -> 1TB01006.01.CN.003C149.01 | O99: ="1TB01006"&"."&J99&"."&I99&"."&D99&".02" -> 1TB01006.01.CN.003C149.02
A100: 1.TB.01.003.01 | B100: AMAALAYachtClub | C100: 2250196 | D100: 003C150 | E100: Al Rajhi Company For Cooperative Insurance | F100: AL RAJHI | G100: Contractor | H100: OCIP Insurance Premium - Declaration 9 | I100: CN | J100: =RIGHT(A100,2) -> 01 | K100: =I100&"."&D100 -> CN.003C150 | L100: =E100&" - "&C100 -> Al Rajhi Company For Cooperative Insurance - 2250196 | M100: ="1TB01006"&"."&J100&"."&I100&"."&D100&".00" -> 1TB01006.01.CN.003C150.00 | N100: ="1TB01006"&"."&J100&"."&I100&"."&D100&".01" -> 1TB01006.01.CN.003C150.01 | O100: ="1TB01006"&"."&J100&"."&I100&"."&D100&".02" -> 1TB01006.01.CN.003C150.02
A101: 1.TB.01.003.01 | B101: AMAALAYachtClub | C101: BAYTUR_PAYMENT | D101: 003C125 | E101: Yaz Development Contracting | F101: YAZ | G101: Contractor | H101: Payment On Behalf Of Saudi Arabian Baytur (Apr) | I101: CN | J101: =RIGHT(A101,2) -> 01 | K101: =I101&"."&D101 -> CN.003C125 | L101: =E101&" - "&C101 -> Yaz Development Contracting - BAYTUR_PAYMENT | M101: ="1TB01006"&"."&J101&"."&I101&"."&D101&".00" -> 1TB01006.01.CN.003C125.00 | N101: ="1TB01006"&"."&J101&"."&I101&"."&D101&".01" -> 1TB01006.01.CN.003C125.01 | O101: ="1TB01006"&"."&J101&"."&I101&"."&D101&".02" -> 1TB01006.01.CN.003C125.02
A102: 1.TB.01.003.01 | B102: AMAALAYachtClub | C102: BAYTUR_PAYMENT | D102: 003C124 | E102: Gesr Alarab | F102: GESR | G102: Contractor | H102: Payment On Behalf Of Saudi Arabian Baytur (Apr) | I102: CN | J102: =RIGHT(A102,2) -> 01 | K102: =I102&"."&D102 -> CN.003C124 | L102: =E102&" - "&C102 -> Gesr Alarab - BAYTUR_PAYMENT | M102: ="1TB01006"&"."&J102&"."&I102&"."&D102&".00" -> 1TB01006.01.CN.003C124.00 | N102: ="1TB01006"&"."&J102&"."&I102&"."&D102&".01" -> 1TB01006.01.CN.003C124.01 | O102: ="1TB01006"&"."&J102&"."&I102&"."&D102&".02" -> 1TB01006.01.CN.003C124.02
A103: 1.TB.01.003.01 | B103: AMAALAYachtClub | C103: BAYTUR_PAYMENT | D103: 003C117 | E103: Abeer Manawer Al-Shamari Contracting Est. | F103: ABEER | G103: Contractor | H103: Payment On Behalf Of Saudi Arabian Baytur (Apr) | I103: CN | J103: =RIGHT(A103,2) -> 01 | K103: =I103&"."&D103 -> CN.003C117 | L103: =E103&" - "&C103 -> Abeer Manawer Al-Shamari Contracting Est. - BAYTUR_PAYMENT | M103: ="1TB01006"&"."&J103&"."&I103&"."&D103&".00" -> 1TB01006.01.CN.003C117.00 | N103: ="1TB01006"&"."&J103&"."&I103&"."&D103&".01" -> 1TB01006.01.CN.003C117.01 | O103: ="1TB01006"&"."&J103&"."&I103&"."&D103&".02" -> 1TB01006.01.CN.003C117.02
...

Sheet Data Input
A1: PROGRAMME: | B1: MARINA VILLAGE (PROGRAMME 1_TRIPLE BAY)
A2: PROGRAMME CODE: | B2: 1TB01003
A3: ASSET NAME: | B3: AMAALA YACHT CLUB | E3: UPDATE INFORMATION IN RED EACH MONTH
A4: ASSET CODE: | B4: 1TB01003.01
A5: Client: | B5: AMAALA
A6: Location: | B6: AL WAJH SAUDI ARABIA
A7: REPORT NO: | B7: MONTHLY REPORT NO. 49
A8: REPORTING PERIOD: | B8: OCTOBER 2026
A9: AMAALA Ref | B9: AMAALA/AYC/MONTHLY REPORT 01
A10: AMAALA Ref | B10: AMAALA/AYC/MONTHLY REPORT 01
A11: Report No Short: | B11: NO. 49
E12: Done | F12: Not Done
A13: TO DO | E13: √ | F13: X
A14: MOM | B14: MINUTES OF MEETINGS | C14: X | E14: √
A15: EXECUTIVE SUMMARY | B15: EXECUTIVE SUMMARY DASHBOARD | C15: X | E15: √
A16: EXECUTIVE SUMMARY | B16: STAKEHOLDER EXECUTIVE REVIEW | C16: X | E16: √
A17: EXECUTIVE SUMMARY | B17: EARLY WARNINGS | C17: X | E17: √
A18: EXECUTIVE SUMMARY | B18: ACC | C18: X | E18: √
A19: SCHEDULE A | B19: LEVEL 1 - EXECUTIVE SUMMARY | C19: X | E19: √
A20: SCHEDULE B | B20: LEVEL 2 - DETAILED SUMMARY | C20: X | E20: √
A21: SCHEDULE C | B21: CHANGE MANAGEMENT TRACKER | C21: X | E21: √
A22: SCHEDULE D | B22: RISK AND OPPORTUNITIES | C22: X | E22: √
A23: SCHEDULE E | B23: CLAIMS AND DISPUTES | C23: X | E23: √
A24: SCHEDULE F | B24: PROVISIONAL SUMS | C24: X | E24: √
A25: SCHEDULE G | B25: BONDS AND INSURANCE TRACKING LOG | C25: X | E25: √
A26: SCHEDULE H | B26: INVOICE AND PAYMENT TRACKING LOG | C26: X | E26: √
A27: SCHEDULE I | B27: CASH FLOW
A28: SCHEDULE J | B28: BUDGET TRANSFER TRACKER
A29: SCHEDULE K | B29: PROCUREMENT STATUS
A31: Distribution
A32: Head of Commercial: | C32: Paul Donaghy
A33: Executive Commercial Director: | C33: Shane Fairfield
A34: Senior Commercial Director: | C34: Michael Hansen
A35: Associate Commercial Director: | C35: Blake Lombard
A37: Senior Project Director: | C37: Christopher Burke
A39: Project Team
A40: Executive Project Director:
A41: Senior Project Director: | C41: Christopher Burke
A42: Planning Director | C42: Sudhakaran Kodicheth
A43: Senior Design Director:
...

Sheet dropdowns
J1: 1 | K1: 2 | L1: 3 | M1: 4 | N1: 5 | O1: 6 | P1: 7 | Q1: 8
B2: Initiated By: | C2: Approval Status | D2: Yes/No: | E2: VE | F2: Change Initiated by | G2: Approval Status Claims: | H2: Contractor or Sub Contractor | I2: Packages | J2: Contractor Details | L2: PS Drop down | M2: Insurances | N2: COST REPORT EFFECTIVE FIGURE | O2: Reporting Period | P2: REFF PO Ref | Q2: VENDOR TYPE
B3: Design Development | C3: APPROVED | D3: YES | E3: Contract | F3: Consultant | G3: Rejected | H3: ALS - Early Works | I3: DAE -Prf Fees | J3: DEWAN ARCHI | L3: PENDING | M3: Professional Indemnity | N3: ACTIVE | O3: Monthly Report No 1 - Oct'22 | P3: 2200340 | Q3: Contractor
B4: Scope Gap | C4: REJECTED | D4: NO | E4: Consultant | F4: Contractor | G4: Approved | H4: JVD - Early Works | I4: HKL (Design Comp Fees)-Prf Fees | J4: HKS Design Consultant | L4: EXPENDED | M4: Third Party Liability | N4: NOT ACTIVE | O4: Monthly Report No 2 - Nov'22 | P4: 2200317 | Q4: Contractor
B5: Scope Overlap | C5: PENDING | E5: Contractor | F5: Employer | G5: Pending | H5: ALS - Main Works | I5: HKL (Design Architect)-Prf Fees | J5: HKS Design Consultant | L5: PARTIALLY EXPENDED | M5: Workmens Compensation | O5: Monthly Report No 3 - Dec'22 | P5: 2200571 | Q5: Contractor
B6: Provisional Sum | C6: REVISED & RE-SUBMIT | G6: Approved inc. in Lump Sum | H6: Five Oceans Marine Survey | I6: ATM-Prf Fees | J6: ATM | M6: Contractors all Risk | O6: Monthly Report No 4 - Jan'23 | P6: 2200571 | Q6: Contractor
B7: Final Account | C7: SUPERSEDED | G7: Approved (Authority) | H7: Becon Development Co | I7: T&T-Prf Fees | J7: Turner & Townsend | M7: Advance Payment Bond | O7: Monthly Report No 5 - Feb'23
B8: Operator's Change | C8: CANCELLED | G8: Approved (proceed to ERI) | H8: WSP Consultants | I8: LUI-Prf Fees | J8: SIC | M8: Performance Bond | O8: Monthly Report No 6 - Mar'23
B9: Contractor's Performance | C9: TRANSFERRED | H9: Five Oceans Coral Relocation | I9: ZFP-Prf Fees | J9: NSCC | M9: Retention Bond | O9: Monthly Report No 7 - Apr'23
B10: EOT - Contractor's Performance | C10: REVIEW COMPLETE | I10: KAA-Mgt Fees | J10: KAA | M10: Marine and Hull | O10: Monthly Report No 8 - May'23
B11: Extension of Time (EOT) | I11: ECC-Mgt Fees | J11: GBC | M11: Plant and Equipment | O11: Monthly Report No 9 - Jun'23
B12: Omission | I12: ECC-Mgt Fees (Accom & Transpo) | J12: CML | M12: Vehicle | O12: Monthly Report No 10 - Jul'23
B13: Omission - Contractor Performance | I13: CML-Mgt Fees | J13: Foster + Partners | M13: Trade License | O13: Monthly Report No 11 - Aug'23
B14: Scope transfer - Contractor's Performance | I14: SOI TB Ground Improvement Works | J14: Langan | O14: Monthly Report No 12 - Sep'23
B15: Contractor's Performance | I15: SOI TB Ground Improvement Works (PS) | J15: Areen | O15: Monthly Report No 13 - Oct'23
B16: Prelims | E16: Initiated By Amaala Representative | G16: Status | I16: GST-LEED Fees | J16: Al Rahji Takaful | O16: Monthly Report No 14 - Nov'23
B17: Back Charge | E17: BLAKE | G17: RFC - Pending from Contractor / Consultant | I17: NSCC - Piling | J17: Baytur | O17: Monthly Report No 15 - Dec'23
E18: FOWZULLAH | G18: RFC - Pending from Engineer | I18: GBC - Sustainability Accreditation | J18: DEPA | O18: Monthly Report No 16 - Jan'24
B19: Project Stage | E19: HANEEF | G19: RFC - Pending to Upload on Aconex | I19: Jensen Hughes-Prf Fees COO 30 | J19: Medtel | O19: Monthly Report No 17 - Feb'24
B20: Pre Contract Variation | E20: JOSE | G20: RFC - Pending for Approval on Aconex | I20: Langan-Prf Fees | J20: New Contractor | O20: Monthly Report No 18 - Mar'24
B21: Post Contract Variation | E21: MIKE . H | G21: RFC - Approved | I21: Langan-Prf Fees (Provisional) | J21: ESCCO | O21: Monthly Report No 19 - Apr'24
B22: Consultant Variation | E22: SHIHAM | G22: RFC - Rejected | I22: Jensen Hughes-Prf Fees | J22: RAQTAN | O22: Monthly Report No 20 - May'24
B23: Pre Contract - Consultant Variation | E23: VASEEF | G23: RFC - Cancelled | I23: Executive Architect Services | J23: ARMETAL | O23: Monthly Report No 21 - Jun'24
B24: Post Contract - Consultant Variation | E24: VEDHAKUMAR | G24: PVO - Pending from Contractor / Consultant | I24: MOM - Building Permit Fee | J24: ALUTEC | O24: Monthly Report No 22 - Jul'24
E25: CLOSED | G25: PVO - Pending from Engineer | I25: Saudi Baytur - Main Works | J25: Al Fanar | O25: Monthly Report No 23 - Aug'24
E26: OTHER | G26: PVO - Pending to Upload on Aconex | I26: SAB - Civil and Arch Works, MEPD & ICT/ELV | J26: Abu Dhabi Precast | O26: Monthly Report No 24 - Sep'24
G27: PVO - Pending for Approval on Aconex | I27: New Contract - Civil and Arch Works, MEPD & ICT/ELV | J27: HAS | O27: Monthly Report No 25 - Oct'24
G28: PVO - Rejected | I28: SAB - Civil and Arch Works | J28: MASS - GRC Works | O28: Monthly Report No 26 - Nov'24
G29: VO - Pending from Contractor / Consultant | I29: SAB - MEPD | J29: Tamimi | O29: Monthly Report No 27 - Dec'24
G30: VO - Pending from Engineer | I30: SAB - ICT / ELV | J30: MAS | O30: Monthly Report No 28 - Jan'25
B31: ACTIONEE | G31: VO - Pending to Upload on Aconex | I31: Medtel - STO Façade Mock-up | J31: KORTEC | O31: Monthly Report No 29 - Feb'25
B32: CLIENT | G32: VO - Pending for Approval on Aconex | I32: ESCCO - Vertical Transport | J32: ALCATOP | O32: Monthly Report No 30 - March'25
B33: ENGINEER | G33: VO - Rejected | I33: Hard and Soft Landscaping | J33: AL FUTTAIM
B34: CONSULTANT | G34: DVO - Pending from Contractor / Consultant | I34: DEPA Interior Fitout | J34: EURO CONSULT
B35: DESIGN CONSULTANT | G35: DVO - Pending from Engineer | I35: FF&E and OSE Procurement Agent | J35: JensenHuges
B36: CONTRACTOR | G36: DVO - Pending to Upload on Aconex | I36: Façade & Glazing Works | J36: TEIJUN
G37: DVO - Pending for Approval on Aconex | I37: RAQTAN - Kitchen and Laundry | J37: IMAR MH3
G38: DVO - Accepted | I38: Loose FF&E items (FOH) | J38: FIBREX MH3
G39: DVO - Rejected | I39: Loose FF&E items (BOH)
I40: Areen - FF&E OS&E Items
...

Sheet MoM
D3: TRIPLE BAY - MARINA VILLAGE - AYC - MONTHLY REPORT
D11: MINUTES OF MEETING
D25: FINANCIAL OVERVIEW | M25: * PROCUREMENT STATUS (CONSTRUCTION RELATED WORKS ONLY) | U25: KEY PERFORMANCE INDICATORS (KPI)
D26: Description | G26: Date Reported | H26: Action | I26: Resolved | M26: Description | P26: Date Reported | Q26: Action | R26: Resolved | U26: Description | X26: Date | Y26: Action | Z26: Resolved
D27: PVO related to NSCC : 1. Savings indicated in the NSCC's PVO to be revisited/reevaluated 2. Since it is a D&B Contract and NSCC proposed design is fit for the purpose, then AMAALA may not be entitled to savings. 3. Notice to NSCC to be issued to proceed with the works to expedite the progress at site 4. Ben advised the changes to be evaluated fairly/ reasonably to pay provided they continue with the works . (For info, BL/MH confirmed Soil investigation report and bore hole (3 No) reports issued to NSCC during RFP stage) | G27: 44874 | H27: Commercial | I27: In Process | U27: Currently 2 No of claims are under review, to be evaluated fairly. | X27: 44874 | Y27: Commercial | Z27: In Process
AD29: 2452499.7
M43: * PROVISIONAL SUMS STATUS (CONSTRUCTION RELATED WORKS ONLY)
D44: KEY PERIOD MOVEMENTS | M44: Description | P44: Date Reported | Q44: Action | R44: Resolved
D45: Description | G45: Date Reported | H45: Action | I45: Resolved
U47: PACKAGE PROGRAMME STATUS
U49: Description | X49: Date | Y49: Action | Z49: Resolved
M53: CHANGE MANAGEMENT OVERVIEW
M54: Description | P54: Date Reported | Q54: Action | R54: Resolved
D65: CURRENT COMMITTED VALUE VS WORKS COMPLETE
D66: Description | G66: Date Reported | H66: Action | I66: Resolved
D67: Dewan fees to be merged in NSCC's final account settlement | G67: 44874 | H67: Commercial | I67: In Process
U72: GENERAL COMMENTS
U74: Description | X74: Date | Y74: Action | Z74: Resolved
E123: Condemned | F123: 0% - 20%
E124: Poor | F124: 21% - 39%
E125: Fair | F125: 40% - 59%
E126: Good | F126: 60% - 75%
E127: As New | F127: 76% - 100%
D183: Option 1 | F183: AED
D184: Option 2 | F184: OMR
D185: Option 3 | F185: 1
D186: 2
D188: 0
D191: BUA ft² | E191: =#REF! -> #REF! | F191: =#REF! -> #REF! | G191: =#REF! -> #REF! | I191: =IF($D$186=1,E191)+IF($D$186=2,F191)+IF($D$186=3,G191)+IF($D$186=4,H191) -> #REF!
D192: GFA ft² | E192: =#REF! -> #REF! | F192: =#REF! -> #REF! | G192: =#REF! -> #REF! | I192: =IF($D$186=1,E192)+IF($D$186=2,F192)+IF($D$186=3,G192)+IF($D$186=4,H192) -> #REF!
D195: BUA m² | E195: =E191/#REF! -> #REF! | F195: =F191/#REF! -> #REF! | G195: =G191/#REF! -> #REF! | I195: =IF($D$186=1,E195)+IF($D$186=2,F195)+IF($D$186=3,G195)+IF($D$186=4,H195) -> #REF!
D196: GFA m² | E196: =E192/#REF! -> #REF! | F196: =F192/#REF! -> #REF! | G196: =G192/#REF! -> #REF! | I196: =IF($D$186=1,E196)+IF($D$186=2,F196)+IF($D$186=3,G196)+IF($D$186=4,H196) -> #REF!
D197: Efficiency | E197: =E196/E195 -> #REF! | F197: =F196/F195 -> #REF! | G197: =G196/G195 -> #REF! | I197: =IF($D$186=1,E197)+IF($D$186=2,F197)+IF($D$186=3,G197)+IF($D$186=4,H197) -> #REF!

Sheet Cover
G25: 33
G26: 35
H39: 45675

Sheet Index
A2: ='Data Input'!A1&" - "&'Data Input'!B1 -> PROGRAMME: - MARINA VILLAGE (PROGRAMME 1_TRIPLE BAY)
A3: ='Data Input'!A2&" - "&'Data Input'!B2 -> PROGRAMME CODE: - 1TB01003
A4: ='Data Input'!A3&" - "&'Data Input'!B3 -> ASSET NAME: - AMAALA YACHT CLUB
A5: ='Data Input'!A4&" - "&'Data Input'!B4 -> ASSET CODE: - 1TB01003.01
A6: ='Data Input'!A7&" - "&'Data Input'!B7 -> REPORT NO: - MONTHLY REPORT NO. 49
A7: ='Data Input'!A8&" - "&'Data Input'!B8 -> REPORTING PERIOD: - OCTOBER 2026
A9: INDEX
G13: PAGE NO
A14: ='Data Input'!A15&" - "&'Data Input'!B15 -> EXECUTIVE SUMMARY - EXECUTIVE SUMMARY DASHBOARD | G14: 2
A15: ='Data Input'!A16&" - "&'Data Input'!B16 -> EXECUTIVE SUMMARY - STAKEHOLDER EXECUTIVE REVIEW | G15: 3
A16: ='Data Input'!A17&" - "&'Data Input'!B17 -> EXECUTIVE SUMMARY - EARLY WARNINGS | G16: 5 | I16: 5,6
A17: ='Data Input'!A18&" - "&'Data Input'!B18 -> EXECUTIVE SUMMARY - ACC | G17: 8 | I17: 7,12
A18: COST REPORT EXECUTIVE SUMMARY - LEVEL 1 | G18: 16
A19: COST REPORT EXECUTIVE SUMMARY - LEVEL 2 | G19: 17
A20: ='Data Input'!A19&" - "&'Data Input'!B19 -> SCHEDULE A - LEVEL 1 - EXECUTIVE SUMMARY | G20: 18
A21: ='Data Input'!A20&" - "&'Data Input'!B20 -> SCHEDULE B - LEVEL 2 - DETAILED SUMMARY | G21: 19 | I21: 16,19
A22: ='Data Input'!A21&" - "&'Data Input'!B21 -> SCHEDULE C - CHANGE MANAGEMENT TRACKER | G22: 23 | I22: 20,26
A23: ='Data Input'!A22&" - "&'Data Input'!B22 -> SCHEDULE D - RISK AND OPPORTUNITIES | G23: 31
A24: ='Data Input'!A23&" - "&'Data Input'!B23 -> SCHEDULE E - CLAIMS AND DISPUTES | G24: 32
A25: ='Data Input'!A24&" - "&'Data Input'!B24 -> SCHEDULE F - PROVISIONAL SUMS | G25: 33
A26: ='Data Input'!A25&" - "&'Data Input'!B25 -> SCHEDULE G - BONDS AND INSURANCE TRACKING LOG | G26: 34 | I26: 30,32
A27: ='Data Input'!A26&" - "&'Data Input'!B26 -> SCHEDULE H - INVOICE AND PAYMENT TRACKING LOG | G27: 37
A28: ='Data Input'!A27&" - "&'Data Input'!B27 -> SCHEDULE I - CASH FLOW | G28: 65
A29: ='Data Input'!A28&" - "&'Data Input'!B28 -> SCHEDULE J - BUDGET TRANSFER TRACKER | G29: 66
A30: ='Data Input'!A29&" - "&'Data Input'!B29 -> SCHEDULE K - PROCUREMENT STATUS | G30: 85
A32: Distribution
A33: ='Data Input'!A32&" - "&'Data Input'!C32 -> Head of Commercial: - Paul Donaghy
A34: ='Data Input'!A33&" - "&'Data Input'!C33 -> Executive Commercial Director: - Shane Fairfield
A35: ='Data Input'!A34&" - "&'Data Input'!C34 -> Senior Commercial Director: - Michael Hansen
A36: ='Data Input'!A35&" - "&'Data Input'!C35 -> Associate Commercial Director: - Blake Lombard
A37: ='Data Input'!A37&" - "&'Data Input'!C37 -> Senior Project Director: - Christopher Burke
A39: PREPARED BY : | D39: REVIEWED BY : | G39: APPROVED BY :
A44: ='Data Input'!A47&" - "&'Data Input'!C47 -> Asst. Manager - Quantity Surveying: - Jose Chavenia | D44: ='Data Input'!A45&" - "&'Data Input'!C45 -> Associate Commercial Director - Blake Lombard | G44: ='Data Input'!A34&" - "&'Data Input'!C34 -> Senior Commercial Director: - Michael Hansen

Sheet Executive Summary
D3: TRIPLE BAY - MARINA VILLAGE - AMAALA YACHT CLUB - MONTHLY REPORT
D25: FINANCIAL OVERVIEW | M25: * PROCUREMENT STATUS (CONSTRUCTION RELATED WORKS ONLY) | U25: KEY PERFORMANCE INDICATORS (KPI)
E27: October 2026 | G27: September 2026 | I27: Period Movement | M27: Contractor / Consultant Package | N27: Original pkg Budget | O27: Revised Package Budget | P27: Variance | Q27: Contract Award | R27: (Saving) / Additional | U27: DETERMINED VARIATION ORDERS (DVO)
D28: Approved / Current Budget | E28: ='Schedule A'!I36 -> 5.8384755e+08 | G28: 5.8449291e+08 | I28: =E28-G28 -> -645354.74 | M28: =D89 -> Construction Works | V28: Total | W28: Previous | X28: Current
M29: PS.003D01 - Dewan Architect | N29: 5973808 | O29: ='Schedule B'!H17 -> 5973808 | P29: =O29-N29 -> 0 | Q29: ='Schedule B'!H17 -> 5973808 | R29: =Q29-N29 -> 0 | U29: Value of PVO (Planned) | V29: =SUMIFS('Schedule C'!$AG$21:$AG$1240,'Schedule C'!$AF$21:$AF$1240,"ACTIVE",'Schedule C'!$AY$21:$AY$1240,"ACTIVE") -> 33878350 | W29: 33878350 | X29: =V29-W29 -> 0
D30: Contracts Awarded | E30: ='Schedule B'!H29+'Schedule B'!H45+'Schedule B'!H73+'Schedule B'!H170+'Schedule B'!H223 -> 5.5345242e+08 | G30: 5.5345242e+08 | I30: =E30-G30 -> 0 | M30: PS.003D02 - HKS Architect - Competition | N30: 555960.36 | O30: ='Schedule B'!H18 -> 555960.36 | P30: =O30-N30 -> 0 | Q30: ='Schedule B'!H18 -> 555960.36 | R30: =Q30-N30 -> 0 | U30: Value of DVO (Actual) | V30: =SUMIFS('Schedule C'!$AZ$21:$AZ$1240,'Schedule C'!$AF$21:$AF$1240,"ACTIVE",'Schedule C'!$AY$21:$AY$1240,"ACTIVE") -> 6873283.8 | W30: 6873283.8 | X30: =V30-W30 -> 0
M31: PS.003D03 - HKS Architect - Design | N31: 10891204 | O31: ='Schedule B'!H19 -> 10891204 | P31: =O31-N31 -> 0 | Q31: ='Schedule B'!H19 -> 10891204 | R31: =Q31-N31 -> 0 | U31: Variance % PVO vs DVO | V31: =IFERROR(((V30-V29)/V30),0) -> -3.9289905 | W31: -3.9289905 | X31: =IFERROR(((X30-X29)/X30),0) -> 0
D32: Committed Procurement Packages | E32: 0 | G32: 0 | I32: =E32-G32 -> 0 | M32: PS.003D04 - Applied Technology | N32: 93750 | O32: ='Schedule B'!H20 -> 93750 | P32: =O32-N32 -> 0 | Q32: ='Schedule B'!H20 -> 93750 | R32: =Q32-N32 -> 0 | U32: Count of DVO Closed | V32: =COUNTIF('Schedule C'!$AY$21:$AY$369,"ACTIVE") -> 118 | W32: 118 | X32: =V32-W32 -> 0
M33: ='Schedule B'!A33&" - "&'Schedule B'!C33 -> MS.003F02 - Khatib & Alami 2230031 | N33: 17975993 | O33: 17975993 | P33: =O33-N33 -> 0 | Q33: ='Schedule B'!H33 -> 13059930 | R33: =Q33-N33 -> -4916063 | U33: DVO Pending < 30 days | V33: =COUNTIFS('Schedule C'!$BA$21:$BA$369,"PENDING",'Schedule C'!$BF$21:$BF$369,"<30") -> 2 | W33: 0 | X33: =V33-W33 -> 2
D34: Determined Variation Orders (DVO) | E34: =+'Schedule B'!I240 -> 6820135.5 | G34: 6820135.5 | I34: =E34-G34 -> 0 | M34: ='Schedule B'!A21&" - "&'Schedule B'!C21 -> PS.003D05 - Langan International UK Limited 2230042 | N34: =+'Schedule B'!H21 -> 172368.42 | O34: =+N34 -> 172368.42 | P34: =O34-N34 -> 0 | Q34: =+'Schedule B'!H21 -> 172368.42 | R34: =Q34-N34 -> 0 | U34: DVO Pending > 30 < 60 days | V34: =COUNTIFS('Schedule C'!$BA$21:$BA$369,"PENDING",'Schedule C'!$BF$21:$BF$369,"<60",'Schedule C'!$BF$21:$BF$369,">=30") -> 1 | W34: 1 | X34: =V34-W34 -> 0
M35: ='Schedule B'!A23&" - "&'Schedule B'!C23 -> PS.003D06 - Ministry of Municipality and Rural Affairs (Tabuk) | N35: =+'Schedule B'!H23 -> 45677.6 | O35: =+N35 -> 45677.6 | P35: =O35-N35 -> 0 | Q35: =+'Schedule B'!H23 -> 45677.6 | R35: =Q35-N35 -> 0 | U35: DVO Pending < 60 > 90 days | V35: =COUNTIFS('Schedule C'!$BA$21:$BA$369,"PENDING",'Schedule C'!$BF$21:$BF$369,"<90",'Schedule C'!$BF$21:$BF$369,">=60") -> 4 | W35: 4 | X35: =V35-W35 -> 0
D36: Committed Costs | E36: =E34+E30+E32 -> 5.6027255e+08 | G36: =G34+G30+G32 -> 5.6027255e+08 | I36: =I34+I30+I32 -> 0 | M36: ='Schedule B'!A22&" - "&'Schedule B'!C22 -> PS.003F01 - Zuhair Fayez and Partners 2230041 | N36: =+'Schedule B'!H22 -> 106231.5 | O36: =+N36 -> 106231.5 | P36: =O36-N36 -> 0 | Q36: =+O36 -> 106231.5 | R36: =Q36-N36 -> 0 | U36: DVO Overdue (>90 days) | V36: =COUNTIFS('Schedule C'!$BA$21:$BA$369,"PENDING",'Schedule C'!$BF$21:$BF$369,">=90") -> 13 | W36: 15 | X36: =V36-W36 -> -2
M37: ='Schedule B'!A24&" - "&'Schedule B'!C24 -> PS.003F04 - Jensen Hughes Saudi Arabia Co 2230180 | N37: =+'Schedule B'!H24 -> 127291.9 | O37: =+N37 -> 127291.9 | P37: =O37-N37 -> 0 | Q37: =+'Schedule B'!H24 -> 127291.9 | R37: =Q37-N37 -> 0
D38: Potential Variation Orders (PVO) | E38: ='Schedule A'!K32+'Schedule A'!H32 -> -16136787 | G38: -16136787 | I38: =E38-G38 -> 0 | M38: PS.003F10 - Langan-Prf Fees COO 30 | O38: =+'Schedule B'!F25 -> 38103.2 | P38: =O38-N38 -> 38103.2 | Q38: 38103.2 | R38: =Q38-N38 -> 38103.2 | U38: 90 DAY CASH FLOWS | V38: MARCH | W38: 2026 | Y38: FORECAST
M39: CN.003C20 - Green Business Cert | N39: 4500 | O39: ='Schedule B'!H71 -> 23094.49 | P39: =O39-N39 -> 18594.49 | Q39: ='Schedule B'!H71 -> 23094.49 | R39: =Q39-N39 -> 18594.49 | U39: VARIANCE | V39: =EOMONTH(W39,-1) -> 46022 | W39: =EOMONTH(X39,-1) -> 46053 | X39: =EOMONTH(Y39,-1) -> 46081 | Y39: =EOMONTH(DATEVALUE(V38&W38),0) -> 46112 | Z39: =EOMONTH(Y39,1) -> 46142
D40: Request for Change (RFC) | E40: ='Schedule A'!L32 -> 3585562.5 | G40: 3801447.7 | I40: =E40-G40 -> -215885.19 | M40: CN.003C13 - SOI TB Gr Improvement | N40: 3082688.7 | O40: =2799717+282972 -> 3082689 | P40: =O40-N40 -> 0.3 | Q40: ='Schedule B'!H69+'Schedule B'!H70 -> 3082689 | R40: =Q40-N40 -> 0.3 | U40: NSCC - Triple Bay Piling (AYC only) | V40: =+'Schedule I'!EI11 -> 0 | W40: =+'Schedule I'!EL11 -> 0 | X40: =+'Schedule I'!EO11 -> 0 | Y40: ='Schedule I'!EP11 -> 0 | Z40: ='Schedule I'!EQ11 -> 0
M41: CN.003C13 - NSCC - Piling - AYC Only | N41: 18698534 | O41: ='Schedule K'!E13 -> 18698534 | P41: =O41-N41 -> 0 | Q41: ='Schedule B'!H77 -> 18698534 | R41: =Q41-N41 -> 0 | U41: DEWAN Architecture | V41: =+'Schedule I'!EI12 -> 0 | W41: =+'Schedule I'!EL12 -> 0 | X41: =+'Schedule I'!EO12 -> 0 | Y41: =+'Schedule I'!EP12 -> 0 | Z41: =+'Schedule I'!EQ12 -> 0
D42: Approved Claims | E42: ='Schedule A'!N32 -> 0 | G42: 0 | I42: =E42-G42 -> 0 | M42: ='Schedule B'!A79&" - "&'Schedule B'!B79 -> CN.003C03 - SAB - Civil and Arch Works, MEPD & ICT/ELV | N42: =105487634.633009+59394214.4019838+4871026.39111685 -> 1.6975288e+08 | O42: =176445278+87209550+9846492 -> 273501320 | P42: =O42-N42 -> 1.0374844e+08 | Q42: ='Schedule B'!H79 -> 2.6095541e+08 | R42: =Q42-N42 -> 91202539 | U42: SIC TB Ground Improvement Works | V42: =+'Schedule I'!EI13 -> 0 | W42: =+'Schedule I'!EL13 -> 0 | X42: =+'Schedule I'!EO13 -> 0 | Y42: =+'Schedule I'!EP13 -> 0 | Z42: =+'Schedule I'!EQ13 -> 0
M43: Direct Payments for SAB's Subcontractors and Suppliers | N43: 0 | O43: 0 | P43: =O43-N43 -> 0 | Q43: =+E94 -> 42594260 | R43: =Q43-N43 -> 42594260 | U43: GBC - Sustainability Accreditation | V43: =+'Schedule I'!EI14 -> 0 | W43: =+'Schedule I'!EL14 -> 0 | X43: =+'Schedule I'!EO14 -> 0 | Y43: =+'Schedule I'!EP14 -> 0 | Z43: =+'Schedule I'!EQ14 -> 0 | AH43: =H68+I48 -> -215885.19
D44: Early Warnings | E44: ='Schedule A'!M32 -> 32891649 | G44: 32891649 | I44: =E44-G44 -> 0 | M44: ='Schedule B'!A148&" - "&'Schedule B'!C148 -> CN.003C21 - STO Façade Mock-up -(MWN) 2230075 | N44: 0 | O44: 0 | P44: =O44-N44 -> 0 | Q44: =+'Schedule B'!H148 -> 834298.55 | R44: =Q44-N44 -> 834298.55 | U44: HKS - Design Competition | V44: =+'Schedule I'!EI15 -> 0 | W44: =+'Schedule I'!EL15 -> 0 | X44: =+'Schedule I'!EO15 -> 0 | Y44: =+'Schedule I'!EP15 -> 0 | Z44: =+'Schedule I'!EQ15 -> 0
M45: ='Schedule B'!A149&" - "&'Schedule B'!C149 -> CN.003F03 - Vertical Transportation (ESCCO) 2230178 | N45: 2153851 | O45: =+'Schedule K'!F17 -> 2675473 | P45: =O45-N45 -> 521622.03 | Q45: ='Schedule B'!H149 -> 2675473 | R45: =Q45-N45 -> 521622.03 | U45: HKS - Design Architect | V45: =+'Schedule I'!EI16 -> 0 | W45: =+'Schedule I'!EL16 -> 0 | X45: =+'Schedule I'!EO16 -> 0 | Y45: =+'Schedule I'!EP16 -> 0 | Z45: =+'Schedule I'!EQ16 -> 0
D46: Uncommitted Cost | E46: =E42+E40+E38+E44 -> 20340424 | G46: =G42+G40+G38+G44 -> 20556309 | I46: =I42+I40+I38+I44 -> -215885.19 | M46: ='Schedule B'!A150&" - "&'Schedule B'!C150 -> CN.003C08 - Kitchen & Laundry Works (Al Raqtan) 2230205 | N46: =+'Schedule K'!C21 -> 5907720 | O46: =+'Schedule K'!E21 -> 4695209 | P46: =O46-N46 -> -1212511 | Q46: =+'Schedule B'!H150 -> 4695209 | R46: =Q46-N46 -> -1212511 | U46: ATM - Rapid review | V46: =+'Schedule I'!EI17 -> 0 | W46: =+'Schedule I'!EL17 -> 0 | X46: =+'Schedule I'!EO17 -> 0 | Y46: =+'Schedule I'!EP17 -> 0 | Z46: =+'Schedule I'!EQ17 -> 0
M47: ='Schedule B'!A151&" - "&'Schedule B'!C151 -> CN.003C09 - Fitout Works (DEPA) | N47: 27478729 | O47: =+' Schedule J SS'!G86 -> 62092796 | P47: =O47-N47 -> 34614067 | Q47: 75969227 | R47: =Q47-N47 -> 48490498 | U47: SAB - AMAALA Yacht Club Construction Contract | V47: =+'Schedule I'!EI18 -> 5755976.9 | W47: =+'Schedule I'!EL18 -> -2856041.1 | X47: =+'Schedule I'!EO18 -> -3483605.8 | Y47: =+'Schedule I'!EP18 -> 0 | Z47: =+'Schedule I'!EQ18 -> 1787346
D48: Current Budget Hold | E48: ='Schedule A'!O34 -> 0 | G48: 0 | I48: =E48-G48 -> 0 | M48: ='Schedule B'!A152&" - "&'Schedule B'!C152 -> CN.003C27 - Façade & Glazing Works (Alutec) | N48: 0 | O48: 0 | P48: =O48-N48 -> 0 | Q48: ='Schedule B'!F152 -> 29899671 | R48: =Q48-N48 -> 29899671 | U48: LANGAN International UK, LTD | V48: =+'Schedule I'!EI19 -> 0 | W48: =+'Schedule I'!EL19 -> 0 | X48: =+'Schedule I'!EO19 -> 0 | Y48: =+'Schedule I'!EP19 -> 0 | Z48: =+'Schedule I'!EQ19 -> 0
M49: MS.003F07 - Euro Consult (COO 6) | N49: 0 | O49: 182184.38 | P49: =O49-N49 -> 182184.38 | Q49: 182184.38 | R49: =Q49-N49 -> 182184.38 | U49: Medtel - W.N. WLL | V49: =+'Schedule I'!EI20 -> 0 | W49: =+'Schedule I'!EL20 -> 0 | X49: =+'Schedule I'!EO20 -> 0 | Y49: =+'Schedule I'!EP20 -> 0 | Z49: =+'Schedule I'!EQ20 -> 0
D50: Projected Cost to Complete | E50: =E48+E46+E36 -> 5.8061298e+08 | G50: =G48+G46+G36 -> 5.8082886e+08 | I50: =I48+I46+I36 -> -215885.19 | M50: MS.003F09 - Euro Consult (COO 27) | N50: 0 | O50: 54000 | P50: =O50-N50 -> 54000 | Q50: 54000 | R50: =Q50-N50 -> 54000 | U50: Raqtan (Kitchen & Laundry) | V50: =+'Schedule I'!EI21 -> 0 | W50: =+'Schedule I'!EL21 -> 0 | X50: =+'Schedule I'!EO21 -> 0 | Y50: =+'Schedule I'!EP21 -> 159337 | Z50: =+'Schedule I'!EQ21 -> 0
M51: FFEOSE.003F06 - FF&E and OSE Procurement Agent (Areen Design Ltd) | N51: 0 | O51: 1107465.9 | P51: =O51-N51 -> 1107465.9 | Q51: 1107465.9 | R51: =Q51-N51 -> 1107465.9 | U51: ESCCO (Vertical Transportation) | V51: =+'Schedule I'!EI22 -> 0 | W51: =+'Schedule I'!EL22 -> 0 | X51: =+'Schedule I'!EO22 -> 0 | Y51: =+'Schedule I'!EP22 -> 334075.28 | Z51: =+'Schedule I'!EQ22 -> 52335.24 | AH51: =V29-V30 -> 27005067
D52: KEY PERIOD MOVEMENTS | M52: PS.003F08 - CML (Independent Commissioning Agent) COO 7 | N52: 0 | O52: 2406500 | P52: =O52-N52 -> 2406500 | Q52: 2406500 | R52: =Q52-N52 -> 2406500 | U52: Khatib & Alami (Management Supervison) | V52: =+'Schedule I'!EI23 -> 0 | W52: =+'Schedule I'!EL23 -> 0 | X52: =+'Schedule I'!EO23 -> 0 | Y52: =+'Schedule I'!EP23 -> 0 | Z52: =+'Schedule I'!EQ23 -> 78720
D53: Description | H53: Amount | M53: ='Schedule B'!A153&" - "&'Schedule B'!C153 -> CN.003C31 - MAS - Wet Works | N53: 0 | O53: 4004000 | P53: =O53-N53 -> 4004000 | Q53: 4004000 | R53: =Q53-N53 -> 4004000 | U53: DEPA (Interior Fitout) | V53: =+'Schedule I'!EI24 -> 0 | W53: =+'Schedule I'!EL24 -> 0 | X53: =+'Schedule I'!EO24 -> 0 | Y53: =+'Schedule I'!EP24 -> 1737945 | Z53: =+'Schedule I'!EQ24 -> 3226545.6
D54: DVO High Level Overview | H54: =+H124 -> 0 | M54: ='Schedule B'!A154&" - "&'Schedule B'!C154 -> CN.003C32 - MAS - Amphitheatre Works | N54: 0 | O54: 1078892.3 | P54: =O54-N54 -> 1078892.3 | Q54: 1078892.3 | R54: =Q54-N54 -> 1078892.3 | U54: ALUTEC | V54: =+'Schedule I'!EI25 -> 0 | W54: =+'Schedule I'!EL25 -> 0 | X54: =+'Schedule I'!EO25 -> 0 | Y54: =+'Schedule I'!EP25 -> 0 | Z54: =+'Schedule I'!EQ25 -> 49611.16
M55: ='Schedule B'!A155&" - "&'Schedule B'!C155 -> CN.003C34 - Al Fanar - MEP Labour Supply | N55: 0 | O55: 23125000 | P55: =O55-N55 -> 23125000 | Q55: 23125000 | R55: =Q55-N55 -> 23125000 | U55: Areen Design | V55: =+'Schedule I'!EI26 -> 0 | W55: =+'Schedule I'!EL26 -> 0 | X55: =+'Schedule I'!EO26 -> 0 | Y55: =+'Schedule I'!EP26 -> 0 | Z55: =+'Schedule I'!EQ26 -> 4331572.5
D56: PVO High Level Overview | H56: =H141 -> 0 | M56: ='Schedule B'!A157&" - "&'Schedule B'!C157 -> CN.003C34 - ARMETAL - Reflective ceiling | N56: 0 | O56: 7129950 | P56: =O56-N56 -> 7129950 | Q56: 7129950 | R56: =Q56-N56 -> 7129950 | U56: =+'Schedule I'!B27 -> MAS Labour | V56: =+'Schedule I'!EI27 -> 0 | W56: =+'Schedule I'!EL27 -> 0 | X56: =+'Schedule I'!EO27 -> 0 | Y56: =+'Schedule I'!EP27 -> 0 | Z56: =+'Schedule I'!EQ27 -> 1016402.2
M57: ='Schedule B'!A158&" - "&'Schedule B'!C158 -> CN.003C34 - Al Rahji Takaful - Owner Controlled Insurance Program | N57: 0 | O57: =+'Schedule B'!F158 -> 89047.06 | P57: =O57-N57 -> 89047.06 | Q57: 73970.78 | R57: =Q57-N57 -> 73970.78 | U57: =+'Schedule I'!B28 -> MAS Amphitheatre | V57: =+'Schedule I'!EI28 -> 0 | W57: =+'Schedule I'!EL28 -> 0 | X57: =+'Schedule I'!EO28 -> 0 | Y57: =+'Schedule I'!EP28 -> 0 | Z57: =+'Schedule I'!EQ28 -> 0
M58: ='Schedule B'!A160&" - "&'Schedule B'!C160 -> CN.003C35 - HASSAN ALLAM - External Scaffoldings | N58: 0 | O58: 3096124.9 | P58: =O58-N58 -> 3096124.9 | Q58: 3096124.9 | R58: =Q58-N58 -> 3096124.9 | U58: =+'Schedule I'!B29 -> Al Fanar Labour | V58: =+'Schedule I'!EI29 -> 0 | W58: =+'Schedule I'!EL29 -> 0 | X58: =+'Schedule I'!EO29 -> 0 | Y58: =+'Schedule I'!EP29 -> 1972028 | Z58: =+'Schedule I'!EQ29 -> 0
D59: RFC High Level Overview | H59: =H164 -> -215885.19 | M59: PS.003F12 - GST - Sustainability Accreditation Services | N59: 0 | O59: 133000 | P59: =O59-N59 -> 133000 | Q59: 133000 | R59: =Q59-N59 -> 133000 | U59: =+'Schedule I'!B30 -> CML | V59: =+'Schedule I'!EI30 -> 0 | W59: =+'Schedule I'!EL30 -> 0 | X59: =+'Schedule I'!EO30 -> 0 | Y59: =+'Schedule I'!EP30 -> 241100 | Z59: =+'Schedule I'!EQ30 -> 164253.85
M60: CN.003CF13 - Enviro - Deep Cleaning | N60: 0 | O60: 799625.31 | P60: =O60-N60 -> 799625.31 | Q60: 799625.31 | R60: =Q60-N60 -> 799625.31 | U60: =+'Schedule I'!B31 -> EuroConsult | V60: =+'Schedule I'!EI31 -> 0 | W60: =+'Schedule I'!EL31 -> 0 | X60: =+'Schedule I'!EO31 -> 0 | Y60: =+'Schedule I'!EP31 -> 15762.54 | Z60: =+'Schedule I'!EQ31 -> 0
M61: ='Schedule B'!A207&" - "&'Schedule B'!C207 -> FFEOSE.003F02 - Loose FF&E Items (FOH) | N61: 12800000 | O61: =+'Schedule K'!F22 -> 25558750 | P61: =O61-N61 -> 12758750 | Q61: Included in the SEED Fund issued as VO to Areen | R61: =IF(SUM(Q61)<=0,0,-SUM(O61)) -> 0 | U61: EuroConsult (Accom and Transport) | V61: =+'Schedule I'!EI32 -> 0 | W61: =+'Schedule I'!EL32 -> 0 | X61: =+'Schedule I'!EO32 -> 0 | Y61: =+'Schedule I'!EP32 -> 0 | Z61: =+'Schedule I'!EQ32 -> 0
D62: Early Warnings/Contract Award | H62: =H200 -> 0 | M62: ='Schedule B'!A208&" - "&'Schedule B'!C208 -> Included in FF&E FOH - Loose FF&E Items (BOH) | N62: 340000 | O62: =+'Schedule K'!F23 -> 470000 | P62: =O62-N62 -> 130000 | R62: =IF(SUM(Q62)<=0,0,-SUM(O62)) -> 0 | U62: Hassan Allam | V62: =+'Schedule I'!EI33 -> 0 | W62: =+'Schedule I'!EL33 -> 0 | X62: =+'Schedule I'!EO33 -> 0 | Y62: =+'Schedule I'!EP33 -> 0 | Z62: =+'Schedule I'!EQ33 -> 0 | AH62: 224
M63: ='Schedule B'!A209&" - "&'Schedule B'!C209 -> FFEOSE.003F02 - OS&E Items | N63: 3543829 | O63: =+'Schedule K'!F24 -> 8681174.6 | P63: =O63-N63 -> 5137345.6 | R63: =IF(SUM(Q63)<=0,0,-SUM(O63)) -> 0 | U63: ARMetal | V63: =+'Schedule I'!EI34 -> 0 | W63: =+'Schedule I'!EL34 -> 0 | X63: =+'Schedule I'!EO34 -> 0 | Y63: =+'Schedule I'!EP34 -> 0 | Z63: =+'Schedule I'!EQ34 -> 0 | AH63: 8
M64: ='Schedule B'!A210&" - "&'Schedule B'!C210 -> Included in OS&E - Art Works | N64: 2400000 | O64: =+'Schedule K'!F25 -> 2874723 | P64: =O64-N64 -> 474723 | R64: =IF(SUM(Q64)<=0,0,-SUM(O64)) -> 0 | U64: Total | V64: =SUM(V40:V63) -> 5755976.9 | W64: =SUM(W40:W63) -> -2856041.1 | X64: =SUM(X40:X63) -> -3483605.8 | Y64: =SUM(Y40:Y63) -> 4460247.8 | Z64: =SUM(Z40:Z63) -> 10706787 | AH64: =SUM(AH62:AH63) -> 232
...

Sheet Stakeholder Executive Review
A2: ='Data Input'!A1&" - "&'Data Input'!B1 -> PROGRAMME: - MARINA VILLAGE (PROGRAMME 1_TRIPLE BAY)
A3: ='Data Input'!A2&" - "&'Data Input'!B2 -> PROGRAMME CODE: - 1TB01003
A4: ='Data Input'!A3&" - "&'Data Input'!B3 -> ASSET NAME: - AMAALA YACHT CLUB
A5: ='Data Input'!A4&" - "&'Data Input'!B4 -> ASSET CODE: - 1TB01003.01
A6: ='Data Input'!A7&" - "&'Data Input'!B7 -> REPORT NO: - MONTHLY REPORT NO. 49
A7: ='Data Input'!A8&" - "&'Data Input'!B8 -> REPORTING PERIOD: - OCTOBER 2026
E9: COMMITTED | H9: UNCOMITTED | Q9: PERIOD MOVEMENT
B10: Approved Baseline Budget | C10: Approved Budget Transfers | D10: Current Approved Budget | E10: Approved Contracts + Direct Actual | F10: Approved Contract Changes (DVOs+PVOs) | G10: Total Approved Commitments | H10: Pending Contracts | I10: Pending Contract Changes (PVOs) | J10: Total Commitments (Approved & Pending) | K10: Early Warnings & RFC | L10: EAC Based on Awarded Packages | M10: Remaining Budget Before EW | N10: Remaining Budget after EW | O10: To Procure (Forecasted Contract Award Value) | P10: Forecasted EAC Including all awards | Q10: ='Schedule B'!X12 -> SEPTEMBER 2026 | R10: Variance | S10: Comments | U10: MH3 Aconex - CN Budget Hold | V10: Variance | W10: MVW | X10: Other Prog 1 Assets | Y10: BTR under Process
B11: A | C11: B | D11: C = (A + B) | E11: D | F11: E | G11: F = (D + E) | H11: G | I11: H | J11: I = (F + G + H) | K11: J | L11: K = (I + J) | M11: L = (F - I) | N11: M = (F - (I+J)) | O11: N | P11: O = (K + N) | Q11: P | R11: Q = (O - P)
D12: To match with "Approved Budget" in Aconex | G12: To match with "Current Commitments" in Aconex | J12: To match with "All Commitments" in Aconex
A13: Professional Services | B13: =SUM(B14:B26) -> 28761589 | C13: =SUM(C14:C26) -> -6705327.7 | D13: =SUM(D14:D26) -> 22056262 | E13: =SUM(E14:E26) -> 22056262 | F13: =SUM(F14:F26) -> 3171766.9 | G13: =SUM(G14:G26) -> 25228028 | H13: =SUM(H14:H26) -> 0 | I13: =SUM(I14:I26) -> 101675.08 | ... R13: =SUM(R14:R26) -> 0 | U13: 1.1835694e+08 | V13: =L13-U13 -> -93046430
A14: ='Schedule B'!C17 -> Dewan Architects & Engineers 2200445 | B14: ='Schedule B'!E17 -> 5973808 | C14: ='Schedule B'!F17 -> 0 | D14: =SUM(B14:C14) -> 5973808 | E14: ='Schedule B'!H17 -> 5973808 | F14: ='Schedule B'!I17+'Schedule B'!J17 -> 3316718.1 | G14: =SUM(E14:F14) -> 9290526.1 | I14: ='Schedule B'!M17 -> 0 | J14: =SUM(G14:I14) -> 9290526.1 | K14: ='Schedule B'!N17+'Schedule B'!O17 -> 0 | L14: =SUM(J14:K14) -> 9290526.1 | M14: =IF(SUM(D14-J14)<0,0,SUM(D14-J14)) -> 0 | N14: =IF(SUM(D14-L14)<0,0,SUM(D14-L14)) -> 0 | P14: =L14+O14 -> 9290526.1 | Q14: ='Schedule B'!X17 -> 9290526.1 | R14: =P14-Q14 -> 0
A15: ='Schedule B'!C18 -> HKS Architects Ltd - Design Competition Fees 2200010 | B15: ='Schedule B'!E18 -> 555960.36 | C15: ='Schedule B'!F18 -> 0 | D15: =SUM(B15:C15) -> 555960.36 | E15: ='Schedule B'!H18 -> 555960.36 | F15: ='Schedule B'!I18+'Schedule B'!J18 -> 0 | G15: =SUM(E15:F15) -> 555960.36 | I15: ='Schedule B'!M18 -> 0 | J15: =SUM(G15:I15) -> 555960.36 | K15: ='Schedule B'!N18+'Schedule B'!O18 -> 0 | L15: =SUM(J15:K15) -> 555960.36 | M15: =IF(SUM(D15-J15)<0,0,SUM(D15-J15)) -> 0 | N15: =IF(SUM(D15-L15)<0,0,SUM(D15-L15)) -> 0 | P15: =L15+O15 -> 555960.36 | Q15: ='Schedule B'!X18 -> 555960.36 | R15: =P15-Q15 -> 0 | S15: Closed - Final account executed.
A16: ='Schedule B'!C19 -> HKS Architects Ltd - Design Architect Fees 2200375 | B16: ='Schedule B'!E19 -> 10891204 | C16: ='Schedule B'!F19 -> 0 | D16: =SUM(B16:C16) -> 10891204 | E16: ='Schedule B'!H19 -> 10891204 | F16: ='Schedule B'!I19+'Schedule B'!J19 -> -89775 | G16: =SUM(E16:F16) -> 10801429 | I16: ='Schedule B'!M19 -> 0 | J16: =SUM(G16:I16) -> 10801429 | K16: ='Schedule B'!N19+'Schedule B'!O19 -> 0 | L16: =SUM(J16:K16) -> 10801429 | M16: =IF(SUM(D16-J16)<0,0,SUM(D16-J16))*0 -> 0 | N16: =IF(SUM(D16-L16)<0,0,SUM(D16-L16))*0 -> 0 | P16: =L16+O16 -> 10801429 | Q16: ='Schedule B'!X19 -> 10801429 | R16: =P16-Q16 -> 0 | S16: Closed - Final account executed.
A17: ='Schedule B'!C20 -> Applied Technology and Management Inc (Dubai BR)s 2210167 | B17: ='Schedule B'!E20 -> 93750 | C17: ='Schedule B'!F20 -> 0 | D17: =SUM(B17:C17) -> 93750 | E17: ='Schedule B'!H20 -> 93750 | F17: ='Schedule B'!I20+'Schedule B'!J20 -> 0 | G17: =SUM(E17:F17) -> 93750 | I17: ='Schedule B'!M20 -> 0 | J17: =SUM(G17:I17) -> 93750 | K17: ='Schedule B'!N20+'Schedule B'!O20 -> 0 | L17: =SUM(J17:K17) -> 93750 | M17: =IF(SUM(D17-J17)<0,0,SUM(D17-J17)) -> 0 | N17: =IF(SUM(D17-L17)<0,0,SUM(D17-L17)) -> 0 | P17: =L17+O17 -> 93750 | Q17: ='Schedule B'!X20 -> 93750 | R17: =P17-Q17 -> 0 | S17: Closed - Final account executed.
A18: ='Schedule B'!C21 -> Langan International UK Limited 2230042 | B18: ='Schedule B'!E21 -> 0 | C18: ='Schedule B'!F21 -> 172368.42 | D18: =SUM(B18:C18) -> 172368.42 | E18: ='Schedule B'!H21 -> 172368.42 | F18: ='Schedule B'!I21+'Schedule B'!J21 -> -1898.52 | G18: =SUM(E18:F18) -> 170469.9 | I18: ='Schedule B'!M21 -> 0 | J18: =SUM(G18:I18) -> 170469.9 | K18: ='Schedule B'!N21+'Schedule B'!O21 -> 0 | L18: =SUM(J18:K18) -> 170469.9 | M18: =IF(SUM(D18-J18)<0,0,SUM(D18-J18)) -> 1898.52 | N18: =IF(SUM(D18-L18)<0,0,SUM(D18-L18)) -> 1898.52 | P18: =L18+O18 -> 170469.9 | Q18: ='Schedule B'!X21 -> 170469.9 | R18: =P18-Q18 -> 0 | S18: Closed - Final account executed.
A19: ='Schedule B'!C22 -> Zuhair Fayez and Partners 2230041 | B19: ='Schedule B'!E22 -> 0 | C19: ='Schedule B'!F22 -> 106231.5 | D19: =SUM(B19:C19) -> 106231.5 | E19: ='Schedule B'!H22 -> 106231.5 | F19: ='Schedule B'!I22+'Schedule B'!J22 -> 0 | G19: =SUM(E19:F19) -> 106231.5 | I19: ='Schedule B'!M22 -> 0 | J19: =SUM(G19:I19) -> 106231.5 | K19: ='Schedule B'!N22+'Schedule B'!O22 -> 0 | L19: =SUM(J19:K19) -> 106231.5 | M19: =IF(SUM(D19-J19)<0,0,SUM(D19-J19)) -> 0 | N19: =IF(SUM(D19-L19)<0,0,SUM(D19-L19)) -> 0 | P19: =L19+O19 -> 106231.5 | Q19: ='Schedule B'!X22 -> 106231.5 | R19: =P19-Q19 -> 0 | S19: Closed - Final account executed.
A20: ='Schedule B'!C23 -> Ministry of Municipality and Rural Affairs (Tabuk) | B20: ='Schedule B'!E23 -> 0 | C20: ='Schedule B'!F23 -> 45677.6 | D20: =SUM(B20:C20) -> 45677.6 | E20: ='Schedule B'!H23 -> 45677.6 | F20: ='Schedule B'!I23+'Schedule B'!J23 -> 0 | G20: =SUM(E20:F20) -> 45677.6 | I20: ='Schedule B'!M23 -> 0 | J20: =SUM(G20:I20) -> 45677.6 | K20: ='Schedule B'!N23+'Schedule B'!O23 -> 0 | L20: =SUM(J20:K20) -> 45677.6 | M20: =IF(SUM(D20-J20)<0,0,SUM(D20-J20)) -> 0 | N20: =IF(SUM(D20-L20)<0,0,SUM(D20-L20)) -> 0 | P20: =L20+O20 -> 45677.6 | Q20: ='Schedule B'!X23 -> 45677.6 | R20: =P20-Q20 -> 0 | S20: Closed - Payment to Tabuk Municipality
