Workbook

Sheet Required actions
A2: Overall Status | C2: Program_01 | D2: Program_02 | E2: Program_03 | F2: Program_04 | G2: Program_05 | H2: Program_06 | I2: Program_07 | J2: Program_08 | K2: Program_09 | L2: Program_10 | M2: Program_11 | N2: Program_12 | O2: Program_16 | P2: Program_17 | Q2: Program_18 | R2: Program_90 | S2: Program_96 | T2: Program_99 | U2: Total
A3: Open | C3: =COUNTIFS(Summary!$A:$A,C$2,Summary!$AV:$AV,$A$3)+COUNTIFS(Summary!$A:$A,C$2,Summary!$AW:$AW,$A$3) -> 83 | D3: =COUNTIFS(Summary!$A:$A,D$2,Summary!$AV:$AV,$A$3)+COUNTIFS(Summary!$A:$A,D$2,Summary!$AW:$AW,$A$3) -> 0 | E3: =COUNTIFS(Summary!$A:$A,E$2,Summary!$AV:$AV,$A$3)+COUNTIFS(Summary!$A:$A,E$2,Summary!$AW:$AW,$A$3) -> 0 | F3: =COUNTIFS(Summary!$A:$A,F$2,Summary!$AV:$AV,$A$3)+COUNTIFS(Summary!$A:$A,F$2,Summary!$AW:$AW,$A$3) -> 0 | G3: =COUNTIFS(Summary!$A:$A,G$2,Summary!$AV:$AV,$A$3)+COUNTIFS(Summary!$A:$A,G$2,Summary!$AW:$AW,$A$3) -> 0 | H3: =COUNTIFS(Summary!$A:$A,H$2,Summary!$AV:$AV,$A$3)+COUNTIFS(Summary!$A:$A,H$2,Summary!$AW:$AW,$A$3) -> 0 | I3: =COUNTIFS(Summary!$A:$A,I$2,Summary!$AV:$AV,$A$3)+COUNTIFS(Summary!$A:$A,I$2,Summary!$AW:$AW,$A$3) -> 0 | J3: =COUNTIFS(Summary!$A:$A,J$2,Summary!$AV:$AV,$A$3)+COUNTIFS(Summary!$A:$A,J$2,Summary!$AW:$AW,$A$3) -> 0 | ... T3: =COUNTIFS(Summary!$A:$A,T$2,Summary!$AV:$AV,$A$3)+COUNTIFS(Summary!$A:$A,T$2,Summary!$AW:$AW,$A$3) -> 0 | U3: =SUM(C3:T3) -> 83
A4: Closed | C4: =COUNTIFS(Summary!$A:$A,C$2,Summary!$AV:$AV,$A$4)+COUNTIFS(Summary!$A:$A,C$2,Summary!$AW:$AW,$A$4) -> 79 | D4: =COUNTIFS(Summary!$A:$A,D$2,Summary!$AV:$AV,$A$4)+COUNTIFS(Summary!$A:$A,D$2,Summary!$AW:$AW,$A$4) -> 0 | E4: =COUNTIFS(Summary!$A:$A,E$2,Summary!$AV:$AV,$A$4)+COUNTIFS(Summary!$A:$A,E$2,Summary!$AW:$AW,$A$4) -> 0 | F4: =COUNTIFS(Summary!$A:$A,F$2,Summary!$AV:$AV,$A$4)+COUNTIFS(Summary!$A:$A,F$2,Summary!$AW:$AW,$A$4) -> 0 | G4: =COUNTIFS(Summary!$A:$A,G$2,Summary!$AV:$AV,$A$4)+COUNTIFS(Summary!$A:$A,G$2,Summary!$AW:$AW,$A$4) -> 0 | H4: =COUNTIFS(Summary!$A:$A,H$2,Summary!$AV:$AV,$A$4)+COUNTIFS(Summary!$A:$A,H$2,Summary!$AW:$AW,$A$4) -> 0 | I4: =COUNTIFS(Summary!$A:$A,I$2,Summary!$AV:$AV,$A$4)+COUNTIFS(Summary!$A:$A,I$2,Summary!$AW:$AW,$A$4) -> 0 | J4: =COUNTIFS(Summary!$A:$A,J$2,Summary!$AV:$AV,$A$4)+COUNTIFS(Summary!$A:$A,J$2,Summary!$AW:$AW,$A$4) -> 0 | ... T4: =COUNTIFS(Summary!$A:$A,T$2,Summary!$AV:$AV,$A$4)+COUNTIFS(Summary!$A:$A,T$2,Summary!$AW:$AW,$A$4) -> 0 | U4: =SUM(C4:T4) -> 79
A5: Total | C5: =SUM(C3:C4) -> 162 | D5: =SUM(D3:D4) -> 0 | E5: =SUM(E3:E4) -> 0 | F5: =SUM(F3:F4) -> 0 | G5: =SUM(G3:G4) -> 0 | H5: =SUM(H3:H4) -> 0 | I5: =SUM(I3:I4) -> 0 | J5: =SUM(J3:J4) -> 0 | ... T5: =SUM(T3:T4) -> 0 | U5: =SUM(C5:T5) -> 162
A7: A | B7: Claims Requiring Response Letter (within 21 days from Claim submission date)
A8: From receipt of Claim | C8: Program_01 | D8: Program_02 | E8: Program_03 | F8: Program_04 | G8: Program_05 | H8: Program_06 | I8: Program_07 | J8: Program_08 | K8: Program_09 | L8: Program_10 | M8: Program_11 | N8: Program_12 | O8: Program_16 | P8: Program_17 | Q8: Program_18 | R8: Program_90 | S8: Program_96 | T8: Program_99 | U8: Total
A9: A1 | B9: 1 to 7 days | C9: =COUNTIFS(Summary!$A:$A,C$8,Summary!$V:$V,0,Summary!$W:$W,">=1",Summary!$W:$W,"<=7") -> 0 | D9: =COUNTIFS(Summary!$A:$A,D$8,Summary!$V:$V,0,Summary!$W:$W,">=1",Summary!$W:$W,"<=7") -> 0 | E9: =COUNTIFS(Summary!$A:$A,E$8,Summary!$V:$V,0,Summary!$W:$W,">=1",Summary!$W:$W,"<=7") -> 0 | F9: =COUNTIFS(Summary!$A:$A,F$8,Summary!$V:$V,0,Summary!$W:$W,">=1",Summary!$W:$W,"<=7") -> 0 | G9: =COUNTIFS(Summary!$A:$A,G$8,Summary!$V:$V,0,Summary!$W:$W,">=1",Summary!$W:$W,"<=7") -> 0 | H9: =COUNTIFS(Summary!$A:$A,H$8,Summary!$V:$V,0,Summary!$W:$W,">=1",Summary!$W:$W,"<=7") -> 0 | I9: =COUNTIFS(Summary!$A:$A,I$8,Summary!$V:$V,0,Summary!$W:$W,">=1",Summary!$W:$W,"<=7") -> 0 | J9: =COUNTIFS(Summary!$A:$A,J$8,Summary!$V:$V,0,Summary!$W:$W,">=1",Summary!$W:$W,"<=7") -> 0 | ... T9: =COUNTIFS(Summary!$A:$A,T$8,Summary!$V:$V,0,Summary!$W:$W,">=1",Summary!$W:$W,"<=7") -> 0 | U9: =SUM(C9:T9) -> 0
A10: A2 | B10: 8 to 14 days | C10: =COUNTIFS(Summary!$A:$A,C$8,Summary!$V:$V,0,Summary!$W:$W,">=8",Summary!$W:$W,"<=14") -> 1 | D10: =COUNTIFS(Summary!$A:$A,D$8,Summary!$V:$V,0,Summary!$W:$W,">=8",Summary!$W:$W,"<=14") -> 0 | E10: =COUNTIFS(Summary!$A:$A,E$8,Summary!$V:$V,0,Summary!$W:$W,">=8",Summary!$W:$W,"<=14") -> 0 | F10: =COUNTIFS(Summary!$A:$A,F$8,Summary!$V:$V,0,Summary!$W:$W,">=8",Summary!$W:$W,"<=14") -> 0 | G10: =COUNTIFS(Summary!$A:$A,G$8,Summary!$V:$V,0,Summary!$W:$W,">=8",Summary!$W:$W,"<=14") -> 0 | H10: =COUNTIFS(Summary!$A:$A,H$8,Summary!$V:$V,0,Summary!$W:$W,">=8",Summary!$W:$W,"<=14") -> 0 | I10: =COUNTIFS(Summary!$A:$A,I$8,Summary!$V:$V,0,Summary!$W:$W,">=8",Summary!$W:$W,"<=14") -> 0 | J10: =COUNTIFS(Summary!$A:$A,J$8,Summary!$V:$V,0,Summary!$W:$W,">=8",Summary!$W:$W,"<=14") -> 0 | ... T10: =COUNTIFS(Summary!$A:$A,T$8,Summary!$V:$V,0,Summary!$W:$W,">=8",Summary!$W:$W,"<=14") -> 0 | U10: =SUM(C10:T10) -> 1
A11: A3 | B11: 15 to 21 days | C11: =COUNTIFS(Summary!$A:$A,C$8,Summary!$V:$V,0,Summary!$W:$W,">=15",Summary!$W:$W,"<=21") -> 1 | D11: =COUNTIFS(Summary!$A:$A,D$8,Summary!$V:$V,0,Summary!$W:$W,">=15",Summary!$W:$W,"<=21") -> 0 | E11: =COUNTIFS(Summary!$A:$A,E$8,Summary!$V:$V,0,Summary!$W:$W,">=15",Summary!$W:$W,"<=21") -> 0 | F11: =COUNTIFS(Summary!$A:$A,F$8,Summary!$V:$V,0,Summary!$W:$W,">=15",Summary!$W:$W,"<=21") -> 0 | G11: =COUNTIFS(Summary!$A:$A,G$8,Summary!$V:$V,0,Summary!$W:$W,">=15",Summary!$W:$W,"<=21") -> 0 | H11: =COUNTIFS(Summary!$A:$A,H$8,Summary!$V:$V,0,Summary!$W:$W,">=15",Summary!$W:$W,"<=21") -> 0 | I11: =COUNTIFS(Summary!$A:$A,I$8,Summary!$V:$V,0,Summary!$W:$W,">=15",Summary!$W:$W,"<=21") -> 0 | J11: =COUNTIFS(Summary!$A:$A,J$8,Summary!$V:$V,0,Summary!$W:$W,">=15",Summary!$W:$W,"<=21") -> 0 | ... T11: =COUNTIFS(Summary!$A:$A,T$8,Summary!$V:$V,0,Summary!$W:$W,">=15",Summary!$W:$W,"<=21") -> 0 | U11: =SUM(C11:T11) -> 1
A12: A4 | B12: Exceeding 21 days | C12: =COUNTIFS(Summary!$A:$A,C$8,Summary!$V:$V,0,Summary!$W:$W,">21") -> 21 | D12: =COUNTIFS(Summary!$A:$A,D$8,Summary!$V:$V,0,Summary!$W:$W,">21") -> 0 | E12: =COUNTIFS(Summary!$A:$A,E$8,Summary!$V:$V,0,Summary!$W:$W,">21") -> 0 | F12: =COUNTIFS(Summary!$A:$A,F$8,Summary!$V:$V,0,Summary!$W:$W,">21") -> 0 | G12: =COUNTIFS(Summary!$A:$A,G$8,Summary!$V:$V,0,Summary!$W:$W,">21") -> 0 | H12: =COUNTIFS(Summary!$A:$A,H$8,Summary!$V:$V,0,Summary!$W:$W,">21") -> 0 | I12: =COUNTIFS(Summary!$A:$A,I$8,Summary!$V:$V,0,Summary!$W:$W,">21") -> 0 | J12: =COUNTIFS(Summary!$A:$A,J$8,Summary!$V:$V,0,Summary!$W:$W,">21") -> 0 | ... T12: =COUNTIFS(Summary!$A:$A,T$8,Summary!$V:$V,0,Summary!$W:$W,">21") -> 0 | U12: =SUM(C12:T12) -> 21
B13: Total | C13: =SUM(C9:C12) -> 23 | D13: =SUM(D9:D12) -> 0 | E13: =SUM(E9:E12) -> 0 | F13: =SUM(F9:F12) -> 0 | G13: =SUM(G9:G12) -> 0 | H13: =SUM(H9:H12) -> 0 | I13: =SUM(I9:I12) -> 0 | J13: =SUM(J9:J12) -> 0 | ... T13: =SUM(T9:T12) -> 0 | U13: =SUM(C13:T13) -> 23
A15: B | B15: Pending Issuance of EoT or Cost Assessment Report
A16: Action With | C16: Program_01 | D16: Program_02 | E16: Program_03 | F16: Program_04 | G16: Program_05 | H16: Program_06 | I16: Program_07 | J16: Program_08 | K16: Program_09 | L16: Program_10 | M16: Program_11 | N16: Program_12 | O16: Program_16 | P16: Program_17 | Q16: Program_18 | R16: Program_90 | S16: Program_96 | T16: Program_99 | U16: Total
A17: B1 | B17: Contractor | C17: =COUNTIFS(Summary!$A:$A,C$16,Summary!$AR:$AR,"Pending",Summary!$AT:$AT,$B17) -> 18 | D17: =COUNTIFS(Summary!$A:$A,D$16,Summary!$AR:$AR,"Pending",Summary!$AT:$AT,$B17) -> 0 | E17: =COUNTIFS(Summary!$A:$A,E$16,Summary!$AR:$AR,"Pending",Summary!$AT:$AT,$B17) -> 0 | F17: =COUNTIFS(Summary!$A:$A,F$16,Summary!$AR:$AR,"Pending",Summary!$AT:$AT,$B17) -> 0 | G17: =COUNTIFS(Summary!$A:$A,G$16,Summary!$AR:$AR,"Pending",Summary!$AT:$AT,$B17) -> 0 | H17: =COUNTIFS(Summary!$A:$A,H$16,Summary!$AR:$AR,"Pending",Summary!$AT:$AT,$B17) -> 0 | I17: =COUNTIFS(Summary!$A:$A,I$16,Summary!$AR:$AR,"Pending",Summary!$AT:$AT,$B17) -> 0 | J17: =COUNTIFS(Summary!$A:$A,J$16,Summary!$AR:$AR,"Pending",Summary!$AT:$AT,$B17) -> 0 | ... T17: =COUNTIFS(Summary!$A:$A,T$16,Summary!$AR:$AR,"Pending",Summary!$AT:$AT,$B17) -> 0 | U17: =SUM(C17:T17) -> 18
A18: B2 | B18: Engineer | C18: =COUNTIFS(Summary!$A:$A,C$16,Summary!$AR:$AR,"Pending",Summary!$AT:$AT,$B18) -> 0 | D18: =COUNTIFS(Summary!$A:$A,D$16,Summary!$AR:$AR,"Pending",Summary!$AT:$AT,$B18) -> 0 | E18: =COUNTIFS(Summary!$A:$A,E$16,Summary!$AR:$AR,"Pending",Summary!$AT:$AT,$B18) -> 0 | F18: =COUNTIFS(Summary!$A:$A,F$16,Summary!$AR:$AR,"Pending",Summary!$AT:$AT,$B18) -> 0 | G18: =COUNTIFS(Summary!$A:$A,G$16,Summary!$AR:$AR,"Pending",Summary!$AT:$AT,$B18) -> 0 | H18: =COUNTIFS(Summary!$A:$A,H$16,Summary!$AR:$AR,"Pending",Summary!$AT:$AT,$B18) -> 0 | I18: =COUNTIFS(Summary!$A:$A,I$16,Summary!$AR:$AR,"Pending",Summary!$AT:$AT,$B18) -> 0 | J18: =COUNTIFS(Summary!$A:$A,J$16,Summary!$AR:$AR,"Pending",Summary!$AT:$AT,$B18) -> 0 | ... T18: =COUNTIFS(Summary!$A:$A,T$16,Summary!$AR:$AR,"Pending",Summary!$AT:$AT,$B18) -> 0 | U18: =SUM(C18:T18) -> 0
A19: B3 | B19: Awaiting conclusion of EoT | C19: =COUNTIFS(Summary!$A:$A,C$16,Summary!$AR:$AR,"Pending",Summary!$AT:$AT,$B19) -> 8 | D19: =COUNTIFS(Summary!$A:$A,D$16,Summary!$AR:$AR,"Pending",Summary!$AT:$AT,$B19) -> 0 | E19: =COUNTIFS(Summary!$A:$A,E$16,Summary!$AR:$AR,"Pending",Summary!$AT:$AT,$B19) -> 0 | F19: =COUNTIFS(Summary!$A:$A,F$16,Summary!$AR:$AR,"Pending",Summary!$AT:$AT,$B19) -> 0 | G19: =COUNTIFS(Summary!$A:$A,G$16,Summary!$AR:$AR,"Pending",Summary!$AT:$AT,$B19) -> 0 | H19: =COUNTIFS(Summary!$A:$A,H$16,Summary!$AR:$AR,"Pending",Summary!$AT:$AT,$B19) -> 0 | I19: =COUNTIFS(Summary!$A:$A,I$16,Summary!$AR:$AR,"Pending",Summary!$AT:$AT,$B19) -> 0 | J19: =COUNTIFS(Summary!$A:$A,J$16,Summary!$AR:$AR,"Pending",Summary!$AT:$AT,$B19) -> 0 | ... T19: =COUNTIFS(Summary!$A:$A,T$16,Summary!$AR:$AR,"Pending",Summary!$AT:$AT,$B19) -> 0 | U19: =SUM(C19:T19) -> 8
A20: B4 | B20: Commercial Team | C20: =COUNTIFS(Summary!$A:$A,C$16,Summary!$AR:$AR,"Pending",Summary!$AT:$AT,$B20) -> 30 | D20: =COUNTIFS(Summary!$A:$A,D$16,Summary!$AR:$AR,"Pending",Summary!$AT:$AT,$B20) -> 0 | E20: =COUNTIFS(Summary!$A:$A,E$16,Summary!$AR:$AR,"Pending",Summary!$AT:$AT,$B20) -> 0 | F20: =COUNTIFS(Summary!$A:$A,F$16,Summary!$AR:$AR,"Pending",Summary!$AT:$AT,$B20) -> 0 | G20: =COUNTIFS(Summary!$A:$A,G$16,Summary!$AR:$AR,"Pending",Summary!$AT:$AT,$B20) -> 0 | H20: =COUNTIFS(Summary!$A:$A,H$16,Summary!$AR:$AR,"Pending",Summary!$AT:$AT,$B20) -> 0 | I20: =COUNTIFS(Summary!$A:$A,I$16,Summary!$AR:$AR,"Pending",Summary!$AT:$AT,$B20) -> 0 | J20: =COUNTIFS(Summary!$A:$A,J$16,Summary!$AR:$AR,"Pending",Summary!$AT:$AT,$B20) -> 0 | ... T20: =COUNTIFS(Summary!$A:$A,T$16,Summary!$AR:$AR,"Pending",Summary!$AT:$AT,$B20) -> 0 | U20: =SUM(C20:T20) -> 30
A21: B5 | B21: Planning Team | C21: =COUNTIFS(Summary!$A:$A,C$16,Summary!$AR:$AR,"Pending",Summary!$AT:$AT,$B21) -> 8 | D21: =COUNTIFS(Summary!$A:$A,D$16,Summary!$AR:$AR,"Pending",Summary!$AT:$AT,$B21) -> 0 | E21: =COUNTIFS(Summary!$A:$A,E$16,Summary!$AR:$AR,"Pending",Summary!$AT:$AT,$B21) -> 0 | F21: =COUNTIFS(Summary!$A:$A,F$16,Summary!$AR:$AR,"Pending",Summary!$AT:$AT,$B21) -> 0 | G21: =COUNTIFS(Summary!$A:$A,G$16,Summary!$AR:$AR,"Pending",Summary!$AT:$AT,$B21) -> 0 | H21: =COUNTIFS(Summary!$A:$A,H$16,Summary!$AR:$AR,"Pending",Summary!$AT:$AT,$B21) -> 0 | I21: =COUNTIFS(Summary!$A:$A,I$16,Summary!$AR:$AR,"Pending",Summary!$AT:$AT,$B21) -> 0 | J21: =COUNTIFS(Summary!$A:$A,J$16,Summary!$AR:$AR,"Pending",Summary!$AT:$AT,$B21) -> 0 | ... T21: =COUNTIFS(Summary!$A:$A,T$16,Summary!$AR:$AR,"Pending",Summary!$AT:$AT,$B21) -> 0 | U21: =SUM(C21:T21) -> 8
A22: B6 | B22: Claims Team | C22: =COUNTIFS(Summary!$A:$A,C$16,Summary!$AR:$AR,"Pending",Summary!$AT:$AT,$B22) -> 4 | D22: =COUNTIFS(Summary!$A:$A,D$16,Summary!$AR:$AR,"Pending",Summary!$AT:$AT,$B22) -> 0 | E22: =COUNTIFS(Summary!$A:$A,E$16,Summary!$AR:$AR,"Pending",Summary!$AT:$AT,$B22) -> 0 | F22: =COUNTIFS(Summary!$A:$A,F$16,Summary!$AR:$AR,"Pending",Summary!$AT:$AT,$B22) -> 0 | G22: =COUNTIFS(Summary!$A:$A,G$16,Summary!$AR:$AR,"Pending",Summary!$AT:$AT,$B22) -> 0 | H22: =COUNTIFS(Summary!$A:$A,H$16,Summary!$AR:$AR,"Pending",Summary!$AT:$AT,$B22) -> 0 | I22: =COUNTIFS(Summary!$A:$A,I$16,Summary!$AR:$AR,"Pending",Summary!$AT:$AT,$B22) -> 0 | J22: =COUNTIFS(Summary!$A:$A,J$16,Summary!$AR:$AR,"Pending",Summary!$AT:$AT,$B22) -> 0 | ... T22: =COUNTIFS(Summary!$A:$A,T$16,Summary!$AR:$AR,"Pending",Summary!$AT:$AT,$B22) -> 0 | U22: =SUM(C22:T22) -> 4
A23: B7 | B23: Legal Team | C23: =COUNTIFS(Summary!$A:$A,C$16,Summary!$AR:$AR,"Pending",Summary!$AT:$AT,$B23) -> 0 | D23: =COUNTIFS(Summary!$A:$A,D$16,Summary!$AR:$AR,"Pending",Summary!$AT:$AT,$B23) -> 0 | E23: =COUNTIFS(Summary!$A:$A,E$16,Summary!$AR:$AR,"Pending",Summary!$AT:$AT,$B23) -> 0 | F23: =COUNTIFS(Summary!$A:$A,F$16,Summary!$AR:$AR,"Pending",Summary!$AT:$AT,$B23) -> 0 | G23: =COUNTIFS(Summary!$A:$A,G$16,Summary!$AR:$AR,"Pending",Summary!$AT:$AT,$B23) -> 0 | H23: =COUNTIFS(Summary!$A:$A,H$16,Summary!$AR:$AR,"Pending",Summary!$AT:$AT,$B23) -> 0 | I23: =COUNTIFS(Summary!$A:$A,I$16,Summary!$AR:$AR,"Pending",Summary!$AT:$AT,$B23) -> 0 | J23: =COUNTIFS(Summary!$A:$A,J$16,Summary!$AR:$AR,"Pending",Summary!$AT:$AT,$B23) -> 0 | ... T23: =COUNTIFS(Summary!$A:$A,T$16,Summary!$AR:$AR,"Pending",Summary!$AT:$AT,$B23) -> 0 | U23: =SUM(C23:T23) -> 0
A24: B8 | B24: For Presentation to Management | C24: =COUNTIFS(Summary!$A:$A,C$16,Summary!$AR:$AR,"Pending",Summary!$AT:$AT,$B24) -> 0 | D24: =COUNTIFS(Summary!$A:$A,D$16,Summary!$AR:$AR,"Pending",Summary!$AT:$AT,$B24) -> 0 | E24: =COUNTIFS(Summary!$A:$A,E$16,Summary!$AR:$AR,"Pending",Summary!$AT:$AT,$B24) -> 0 | F24: =COUNTIFS(Summary!$A:$A,F$16,Summary!$AR:$AR,"Pending",Summary!$AT:$AT,$B24) -> 0 | G24: =COUNTIFS(Summary!$A:$A,G$16,Summary!$AR:$AR,"Pending",Summary!$AT:$AT,$B24) -> 0 | H24: =COUNTIFS(Summary!$A:$A,H$16,Summary!$AR:$AR,"Pending",Summary!$AT:$AT,$B24) -> 0 | I24: =COUNTIFS(Summary!$A:$A,I$16,Summary!$AR:$AR,"Pending",Summary!$AT:$AT,$B24) -> 0 | J24: =COUNTIFS(Summary!$A:$A,J$16,Summary!$AR:$AR,"Pending",Summary!$AT:$AT,$B24) -> 0 | ... T24: =COUNTIFS(Summary!$A:$A,T$16,Summary!$AR:$AR,"Pending",Summary!$AT:$AT,$B24) -> 0 | U24: =SUM(C24:T24) -> 0
A25: B9 | B25: Assessment in WF | C25: =COUNTIFS(Summary!$A:$A,C$16,Summary!$AR:$AR,"Pending",Summary!$AT:$AT,$B25) -> 0 | D25: =COUNTIFS(Summary!$A:$A,D$16,Summary!$AR:$AR,"Pending",Summary!$AT:$AT,$B25) -> 0 | E25: =COUNTIFS(Summary!$A:$A,E$16,Summary!$AR:$AR,"Pending",Summary!$AT:$AT,$B25) -> 0 | F25: =COUNTIFS(Summary!$A:$A,F$16,Summary!$AR:$AR,"Pending",Summary!$AT:$AT,$B25) -> 0 | G25: =COUNTIFS(Summary!$A:$A,G$16,Summary!$AR:$AR,"Pending",Summary!$AT:$AT,$B25) -> 0 | H25: =COUNTIFS(Summary!$A:$A,H$16,Summary!$AR:$AR,"Pending",Summary!$AT:$AT,$B25) -> 0 | I25: =COUNTIFS(Summary!$A:$A,I$16,Summary!$AR:$AR,"Pending",Summary!$AT:$AT,$B25) -> 0 | J25: =COUNTIFS(Summary!$A:$A,J$16,Summary!$AR:$AR,"Pending",Summary!$AT:$AT,$B25) -> 0 | ... T25: =COUNTIFS(Summary!$A:$A,T$16,Summary!$AR:$AR,"Pending",Summary!$AT:$AT,$B25) -> 0 | U25: =SUM(C25:T25) -> 0
A26: Total | C26: =SUM(C17:C25) -> 68 | D26: =SUM(D17:D25) -> 0 | E26: =SUM(E17:E25) -> 0 | F26: =SUM(F17:F25) -> 0 | G26: =SUM(G17:G25) -> 0 | H26: =SUM(H17:H25) -> 0 | I26: =SUM(I17:I25) -> 0 | J26: =SUM(J17:J25) -> 0 | ... T26: =SUM(T17:T25) -> 0 | U26: =SUM(C26:T26) -> 68
A28: C | B28: Pending Issuance of DVO/VO/CA
A29: Action With | C29: Program_01 | D29: Program_02 | E29: Program_03 | F29: Program_04 | G29: Program_05 | H29: Program_06 | I29: Program_07 | J29: Program_08 | K29: Program_09 | L29: Program_10 | M29: Program_11 | N29: Program_12 | O29: Program_16 | P29: Program_17 | Q29: Program_18 | R29: Program_90 | S29: Program_96 | T29: Program_99 | U29: Total
A30: C1 | B30: Contractor | C30: =COUNTIFS(Summary!$A:$A,C$29,Summary!$AR:$AR,"Assessment Report Issued",Summary!$AS:$AS,"Open",Summary!$AT:$AT,$B30) -> 5 | D30: =COUNTIFS(Summary!$A:$A,D$29,Summary!$AR:$AR,"Assessment Report Issued",Summary!$AS:$AS,"Open",Summary!$AT:$AT,$B30) -> 0 | E30: =COUNTIFS(Summary!$A:$A,E$29,Summary!$AR:$AR,"Assessment Report Issued",Summary!$AS:$AS,"Open",Summary!$AT:$AT,$B30) -> 0 | F30: =COUNTIFS(Summary!$A:$A,F$29,Summary!$AR:$AR,"Assessment Report Issued",Summary!$AS:$AS,"Open",Summary!$AT:$AT,$B30) -> 0 | G30: =COUNTIFS(Summary!$A:$A,G$29,Summary!$AR:$AR,"Assessment Report Issued",Summary!$AS:$AS,"Open",Summary!$AT:$AT,$B30) -> 0 | H30: =COUNTIFS(Summary!$A:$A,H$29,Summary!$AR:$AR,"Assessment Report Issued",Summary!$AS:$AS,"Open",Summary!$AT:$AT,$B30) -> 0 | I30: =COUNTIFS(Summary!$A:$A,I$29,Summary!$AR:$AR,"Assessment Report Issued",Summary!$AS:$AS,"Open",Summary!$AT:$AT,$B30) -> 0 | J30: =COUNTIFS(Summary!$A:$A,J$29,Summary!$AR:$AR,"Assessment Report Issued",Summary!$AS:$AS,"Open",Summary!$AT:$AT,$B30) -> 0 | ... T30: =COUNTIFS(Summary!$A:$A,T$29,Summary!$AR:$AR,"Assessment Report Issued",Summary!$AS:$AS,"Open",Summary!$AT:$AT,$B30) -> 0 | U30: =SUM(C30:T30) -> 5
A31: C2 | B31: Engineer | C31: =COUNTIFS(Summary!$A:$A,C$29,Summary!$AR:$AR,"Assessment Report Issued",Summary!$AS:$AS,"Open",Summary!$AT:$AT,$B31) -> 0 | D31: =COUNTIFS(Summary!$A:$A,D$29,Summary!$AR:$AR,"Assessment Report Issued",Summary!$AS:$AS,"Open",Summary!$AT:$AT,$B31) -> 0 | E31: =COUNTIFS(Summary!$A:$A,E$29,Summary!$AR:$AR,"Assessment Report Issued",Summary!$AS:$AS,"Open",Summary!$AT:$AT,$B31) -> 0 | F31: =COUNTIFS(Summary!$A:$A,F$29,Summary!$AR:$AR,"Assessment Report Issued",Summary!$AS:$AS,"Open",Summary!$AT:$AT,$B31) -> 0 | G31: =COUNTIFS(Summary!$A:$A,G$29,Summary!$AR:$AR,"Assessment Report Issued",Summary!$AS:$AS,"Open",Summary!$AT:$AT,$B31) -> 0 | H31: =COUNTIFS(Summary!$A:$A,H$29,Summary!$AR:$AR,"Assessment Report Issued",Summary!$AS:$AS,"Open",Summary!$AT:$AT,$B31) -> 0 | I31: =COUNTIFS(Summary!$A:$A,I$29,Summary!$AR:$AR,"Assessment Report Issued",Summary!$AS:$AS,"Open",Summary!$AT:$AT,$B31) -> 0 | J31: =COUNTIFS(Summary!$A:$A,J$29,Summary!$AR:$AR,"Assessment Report Issued",Summary!$AS:$AS,"Open",Summary!$AT:$AT,$B31) -> 0 | ... T31: =COUNTIFS(Summary!$A:$A,T$29,Summary!$AR:$AR,"Assessment Report Issued",Summary!$AS:$AS,"Open",Summary!$AT:$AT,$B31) -> 0 | U31: =SUM(C31:T31) -> 0
A32: C3 | B32: Commercial Team | C32: =COUNTIFS(Summary!$A:$A,C$29,Summary!$AR:$AR,"Assessment Report Issued",Summary!$AS:$AS,"Open",Summary!$AT:$AT,$B32) -> 3 | D32: =COUNTIFS(Summary!$A:$A,D$29,Summary!$AR:$AR,"Assessment Report Issued",Summary!$AS:$AS,"Open",Summary!$AT:$AT,$B32) -> 0 | E32: =COUNTIFS(Summary!$A:$A,E$29,Summary!$AR:$AR,"Assessment Report Issued",Summary!$AS:$AS,"Open",Summary!$AT:$AT,$B32) -> 0 | F32: =COUNTIFS(Summary!$A:$A,F$29,Summary!$AR:$AR,"Assessment Report Issued",Summary!$AS:$AS,"Open",Summary!$AT:$AT,$B32) -> 0 | G32: =COUNTIFS(Summary!$A:$A,G$29,Summary!$AR:$AR,"Assessment Report Issued",Summary!$AS:$AS,"Open",Summary!$AT:$AT,$B32) -> 0 | H32: =COUNTIFS(Summary!$A:$A,H$29,Summary!$AR:$AR,"Assessment Report Issued",Summary!$AS:$AS,"Open",Summary!$AT:$AT,$B32) -> 0 | I32: =COUNTIFS(Summary!$A:$A,I$29,Summary!$AR:$AR,"Assessment Report Issued",Summary!$AS:$AS,"Open",Summary!$AT:$AT,$B32) -> 0 | J32: =COUNTIFS(Summary!$A:$A,J$29,Summary!$AR:$AR,"Assessment Report Issued",Summary!$AS:$AS,"Open",Summary!$AT:$AT,$B32) -> 0 | ... T32: =COUNTIFS(Summary!$A:$A,T$29,Summary!$AR:$AR,"Assessment Report Issued",Summary!$AS:$AS,"Open",Summary!$AT:$AT,$B32) -> 0 | U32: =SUM(C32:T32) -> 3 | W32: Open Claims | Y32: Total
A33: C5 | B33: Planning Team | C33: =COUNTIFS(Summary!$A:$A,C$29,Summary!$AR:$AR,"Assessment Report Issued",Summary!$AS:$AS,"Open",Summary!$AT:$AT,$B33) -> 1 | D33: =COUNTIFS(Summary!$A:$A,D$29,Summary!$AR:$AR,"Assessment Report Issued",Summary!$AS:$AS,"Open",Summary!$AT:$AT,$B33) -> 0 | E33: =COUNTIFS(Summary!$A:$A,E$29,Summary!$AR:$AR,"Assessment Report Issued",Summary!$AS:$AS,"Open",Summary!$AT:$AT,$B33) -> 0 | F33: =COUNTIFS(Summary!$A:$A,F$29,Summary!$AR:$AR,"Assessment Report Issued",Summary!$AS:$AS,"Open",Summary!$AT:$AT,$B33) -> 0 | G33: =COUNTIFS(Summary!$A:$A,G$29,Summary!$AR:$AR,"Assessment Report Issued",Summary!$AS:$AS,"Open",Summary!$AT:$AT,$B33) -> 0 | H33: =COUNTIFS(Summary!$A:$A,H$29,Summary!$AR:$AR,"Assessment Report Issued",Summary!$AS:$AS,"Open",Summary!$AT:$AT,$B33) -> 0 | I33: =COUNTIFS(Summary!$A:$A,I$29,Summary!$AR:$AR,"Assessment Report Issued",Summary!$AS:$AS,"Open",Summary!$AT:$AT,$B33) -> 0 | J33: =COUNTIFS(Summary!$A:$A,J$29,Summary!$AR:$AR,"Assessment Report Issued",Summary!$AS:$AS,"Open",Summary!$AT:$AT,$B33) -> 0 | ... T33: =COUNTIFS(Summary!$A:$A,T$29,Summary!$AR:$AR,"Assessment Report Issued",Summary!$AS:$AS,"Open",Summary!$AT:$AT,$B33) -> 0 | U33: =SUM(C33:T33) -> 1 | W33: B + C + D | Y33: =U26+U36+U45 -> 77
A34: C6 | B34: Claims Team | C34: =COUNTIFS(Summary!$A:$A,C$29,Summary!$AR:$AR,"Assessment Report Issued",Summary!$AS:$AS,"Open",Summary!$AT:$AT,$B34) -> 0 | D34: =COUNTIFS(Summary!$A:$A,D$29,Summary!$AR:$AR,"Assessment Report Issued",Summary!$AS:$AS,"Open",Summary!$AT:$AT,$B34) -> 0 | E34: =COUNTIFS(Summary!$A:$A,E$29,Summary!$AR:$AR,"Assessment Report Issued",Summary!$AS:$AS,"Open",Summary!$AT:$AT,$B34) -> 0 | F34: =COUNTIFS(Summary!$A:$A,F$29,Summary!$AR:$AR,"Assessment Report Issued",Summary!$AS:$AS,"Open",Summary!$AT:$AT,$B34) -> 0 | G34: =COUNTIFS(Summary!$A:$A,G$29,Summary!$AR:$AR,"Assessment Report Issued",Summary!$AS:$AS,"Open",Summary!$AT:$AT,$B34) -> 0 | H34: =COUNTIFS(Summary!$A:$A,H$29,Summary!$AR:$AR,"Assessment Report Issued",Summary!$AS:$AS,"Open",Summary!$AT:$AT,$B34) -> 0 | I34: =COUNTIFS(Summary!$A:$A,I$29,Summary!$AR:$AR,"Assessment Report Issued",Summary!$AS:$AS,"Open",Summary!$AT:$AT,$B34) -> 0 | J34: =COUNTIFS(Summary!$A:$A,J$29,Summary!$AR:$AR,"Assessment Report Issued",Summary!$AS:$AS,"Open",Summary!$AT:$AT,$B34) -> 0 | ... T34: =COUNTIFS(Summary!$A:$A,T$29,Summary!$AR:$AR,"Assessment Report Issued",Summary!$AS:$AS,"Open",Summary!$AT:$AT,$B34) -> 0 | U34: =SUM(C34:T34) -> 0
A35: C7 | B35: DVO/VO in WF | C35: =COUNTIFS(Summary!$A:$A,C$29,Summary!$AR:$AR,"Assessment Report Issued",Summary!$AS:$AS,"Open",Summary!$AT:$AT,$B35) -> 0 | D35: =COUNTIFS(Summary!$A:$A,D$29,Summary!$AR:$AR,"Assessment Report Issued",Summary!$AS:$AS,"Open",Summary!$AT:$AT,$B35) -> 0 | E35: =COUNTIFS(Summary!$A:$A,E$29,Summary!$AR:$AR,"Assessment Report Issued",Summary!$AS:$AS,"Open",Summary!$AT:$AT,$B35) -> 0 | F35: =COUNTIFS(Summary!$A:$A,F$29,Summary!$AR:$AR,"Assessment Report Issued",Summary!$AS:$AS,"Open",Summary!$AT:$AT,$B35) -> 0 | G35: =COUNTIFS(Summary!$A:$A,G$29,Summary!$AR:$AR,"Assessment Report Issued",Summary!$AS:$AS,"Open",Summary!$AT:$AT,$B35) -> 0 | H35: =COUNTIFS(Summary!$A:$A,H$29,Summary!$AR:$AR,"Assessment Report Issued",Summary!$AS:$AS,"Open",Summary!$AT:$AT,$B35) -> 0 | I35: =COUNTIFS(Summary!$A:$A,I$29,Summary!$AR:$AR,"Assessment Report Issued",Summary!$AS:$AS,"Open",Summary!$AT:$AT,$B35) -> 0 | J35: =COUNTIFS(Summary!$A:$A,J$29,Summary!$AR:$AR,"Assessment Report Issued",Summary!$AS:$AS,"Open",Summary!$AT:$AT,$B35) -> 0 | ... T35: =COUNTIFS(Summary!$A:$A,T$29,Summary!$AR:$AR,"Assessment Report Issued",Summary!$AS:$AS,"Open",Summary!$AT:$AT,$B35) -> 0 | U35: =SUM(C35:T35) -> 0
A36: Total | C36: =SUM(C30:C35) -> 9 | D36: =SUM(D30:D35) -> 0 | E36: =SUM(E30:E35) -> 0 | F36: =SUM(F30:F35) -> 0 | G36: =SUM(G30:G35) -> 0 | H36: =SUM(H30:H35) -> 0 | I36: =SUM(I30:I35) -> 0 | J36: =SUM(J30:J35) -> 0 | ... T36: =SUM(T30:T35) -> 0 | U36: =SUM(C36:T36) -> 9
A38: D | B38: Pending Full Closure of Claim (Assessment Report & DVO/VO/CA Issued)
A39: Action With | C39: Program_01 | D39: Program_02 | E39: Program_03 | F39: Program_04 | G39: Program_05 | H39: Program_06 | I39: Program_07 | J39: Program_08 | K39: Program_09 | L39: Program_10 | M39: Program_11 | N39: Program_12 | O39: Program_16 | P39: Program_17 | Q39: Program_18 | R39: Program_90 | S39: Program_96 | T39: Program_99 | U39: Total
A40: D1 | B40: Contractor | C40: =COUNTIFS(Summary!$A:$A,C$39,Summary!$AR:$AR,"<>Pending",Summary!$AS:$AS,"<>Open",Summary!$AT:$AT,$B40) -> 0 | D40: =COUNTIFS(Summary!$A:$A,D$39,Summary!$AR:$AR,"<>Pending",Summary!$AS:$AS,"<>Open",Summary!$AT:$AT,$B40) -> 0 | E40: =COUNTIFS(Summary!$A:$A,E$39,Summary!$AR:$AR,"<>Pending",Summary!$AS:$AS,"<>Open",Summary!$AT:$AT,$B40) -> 0 | F40: =COUNTIFS(Summary!$A:$A,F$39,Summary!$AR:$AR,"<>Pending",Summary!$AS:$AS,"<>Open",Summary!$AT:$AT,$B40) -> 0 | G40: =COUNTIFS(Summary!$A:$A,G$39,Summary!$AR:$AR,"<>Pending",Summary!$AS:$AS,"<>Open",Summary!$AT:$AT,$B40) -> 0 | H40: =COUNTIFS(Summary!$A:$A,H$39,Summary!$AR:$AR,"<>Pending",Summary!$AS:$AS,"<>Open",Summary!$AT:$AT,$B40) -> 0 | I40: =COUNTIFS(Summary!$A:$A,I$39,Summary!$AR:$AR,"<>Pending",Summary!$AS:$AS,"<>Open",Summary!$AT:$AT,$B40) -> 0 | J40: =COUNTIFS(Summary!$A:$A,J$39,Summary!$AR:$AR,"<>Pending",Summary!$AS:$AS,"<>Open",Summary!$AT:$AT,$B40) -> 0 | ... T40: =COUNTIFS(Summary!$A:$A,T$39,Summary!$AR:$AR,"<>Pending",Summary!$AS:$AS,"<>Open",Summary!$AT:$AT,$B40) -> 0 | U40: =SUM(C40:T40) -> 0
A41: D2 | B41: Commercial Team | C41: =COUNTIFS(Summary!$A:$A,C$39,Summary!$AR:$AR,"<>Pending",Summary!$AS:$AS,"<>Open",Summary!$AT:$AT,$B41) -> 0 | D41: =COUNTIFS(Summary!$A:$A,D$39,Summary!$AR:$AR,"<>Pending",Summary!$AS:$AS,"<>Open",Summary!$AT:$AT,$B41) -> 0 | E41: =COUNTIFS(Summary!$A:$A,E$39,Summary!$AR:$AR,"<>Pending",Summary!$AS:$AS,"<>Open",Summary!$AT:$AT,$B41) -> 0 | F41: =COUNTIFS(Summary!$A:$A,F$39,Summary!$AR:$AR,"<>Pending",Summary!$AS:$AS,"<>Open",Summary!$AT:$AT,$B41) -> 0 | G41: =COUNTIFS(Summary!$A:$A,G$39,Summary!$AR:$AR,"<>Pending",Summary!$AS:$AS,"<>Open",Summary!$AT:$AT,$B41) -> 0 | H41: =COUNTIFS(Summary!$A:$A,H$39,Summary!$AR:$AR,"<>Pending",Summary!$AS:$AS,"<>Open",Summary!$AT:$AT,$B41) -> 0 | I41: =COUNTIFS(Summary!$A:$A,I$39,Summary!$AR:$AR,"<>Pending",Summary!$AS:$AS,"<>Open",Summary!$AT:$AT,$B41) -> 0 | J41: =COUNTIFS(Summary!$A:$A,J$39,Summary!$AR:$AR,"<>Pending",Summary!$AS:$AS,"<>Open",Summary!$AT:$AT,$B41) -> 0 | ... T41: =COUNTIFS(Summary!$A:$A,T$39,Summary!$AR:$AR,"<>Pending",Summary!$AS:$AS,"<>Open",Summary!$AT:$AT,$B41) -> 0 | U41: =SUM(C41:T41) -> 0
A42: D3 | B42: Planning Team | C42: =COUNTIFS(Summary!$A:$A,C$39,Summary!$AR:$AR,"<>Pending",Summary!$AS:$AS,"<>Open",Summary!$AT:$AT,$B42) -> 0 | D42: =COUNTIFS(Summary!$A:$A,D$39,Summary!$AR:$AR,"<>Pending",Summary!$AS:$AS,"<>Open",Summary!$AT:$AT,$B42) -> 0 | E42: =COUNTIFS(Summary!$A:$A,E$39,Summary!$AR:$AR,"<>Pending",Summary!$AS:$AS,"<>Open",Summary!$AT:$AT,$B42) -> 0 | F42: =COUNTIFS(Summary!$A:$A,F$39,Summary!$AR:$AR,"<>Pending",Summary!$AS:$AS,"<>Open",Summary!$AT:$AT,$B42) -> 0 | G42: =COUNTIFS(Summary!$A:$A,G$39,Summary!$AR:$AR,"<>Pending",Summary!$AS:$AS,"<>Open",Summary!$AT:$AT,$B42) -> 0 | H42: =COUNTIFS(Summary!$A:$A,H$39,Summary!$AR:$AR,"<>Pending",Summary!$AS:$AS,"<>Open",Summary!$AT:$AT,$B42) -> 0 | I42: =COUNTIFS(Summary!$A:$A,I$39,Summary!$AR:$AR,"<>Pending",Summary!$AS:$AS,"<>Open",Summary!$AT:$AT,$B42) -> 0 | J42: =COUNTIFS(Summary!$A:$A,J$39,Summary!$AR:$AR,"<>Pending",Summary!$AS:$AS,"<>Open",Summary!$AT:$AT,$B42) -> 0 | ... T42: =COUNTIFS(Summary!$A:$A,T$39,Summary!$AR:$AR,"<>Pending",Summary!$AS:$AS,"<>Open",Summary!$AT:$AT,$B42) -> 0 | U42: =SUM(C42:T42) -> 0
A43: D4 | B43: Claims Team | C43: =COUNTIFS(Summary!$A:$A,C$39,Summary!$AR:$AR,"<>Pending",Summary!$AS:$AS,"<>Open",Summary!$AT:$AT,$B43) -> 0 | D43: =COUNTIFS(Summary!$A:$A,D$39,Summary!$AR:$AR,"<>Pending",Summary!$AS:$AS,"<>Open",Summary!$AT:$AT,$B43) -> 0 | E43: =COUNTIFS(Summary!$A:$A,E$39,Summary!$AR:$AR,"<>Pending",Summary!$AS:$AS,"<>Open",Summary!$AT:$AT,$B43) -> 0 | F43: =COUNTIFS(Summary!$A:$A,F$39,Summary!$AR:$AR,"<>Pending",Summary!$AS:$AS,"<>Open",Summary!$AT:$AT,$B43) -> 0 | G43: =COUNTIFS(Summary!$A:$A,G$39,Summary!$AR:$AR,"<>Pending",Summary!$AS:$AS,"<>Open",Summary!$AT:$AT,$B43) -> 0 | H43: =COUNTIFS(Summary!$A:$A,H$39,Summary!$AR:$AR,"<>Pending",Summary!$AS:$AS,"<>Open",Summary!$AT:$AT,$B43) -> 0 | I43: =COUNTIFS(Summary!$A:$A,I$39,Summary!$AR:$AR,"<>Pending",Summary!$AS:$AS,"<>Open",Summary!$AT:$AT,$B43) -> 0 | J43: =COUNTIFS(Summary!$A:$A,J$39,Summary!$AR:$AR,"<>Pending",Summary!$AS:$AS,"<>Open",Summary!$AT:$AT,$B43) -> 0 | ... T43: =COUNTIFS(Summary!$A:$A,T$39,Summary!$AR:$AR,"<>Pending",Summary!$AS:$AS,"<>Open",Summary!$AT:$AT,$B43) -> 0 | U43: =SUM(C43:T43) -> 0
A44: D5 | B44: Legal Team | C44: =COUNTIFS(Summary!$A:$A,C$39,Summary!$AR:$AR,"<>Pending",Summary!$AS:$AS,"<>Open",Summary!$AT:$AT,$B44) -> 0 | D44: =COUNTIFS(Summary!$A:$A,D$39,Summary!$AR:$AR,"<>Pending",Summary!$AS:$AS,"<>Open",Summary!$AT:$AT,$B44) -> 0 | E44: =COUNTIFS(Summary!$A:$A,E$39,Summary!$AR:$AR,"<>Pending",Summary!$AS:$AS,"<>Open",Summary!$AT:$AT,$B44) -> 0 | F44: =COUNTIFS(Summary!$A:$A,F$39,Summary!$AR:$AR,"<>Pending",Summary!$AS:$AS,"<>Open",Summary!$AT:$AT,$B44) -> 0 | G44: =COUNTIFS(Summary!$A:$A,G$39,Summary!$AR:$AR,"<>Pending",Summary!$AS:$AS,"<>Open",Summary!$AT:$AT,$B44) -> 0 | H44: =COUNTIFS(Summary!$A:$A,H$39,Summary!$AR:$AR,"<>Pending",Summary!$AS:$AS,"<>Open",Summary!$AT:$AT,$B44) -> 0 | I44: =COUNTIFS(Summary!$A:$A,I$39,Summary!$AR:$AR,"<>Pending",Summary!$AS:$AS,"<>Open",Summary!$AT:$AT,$B44) -> 0 | J44: =COUNTIFS(Summary!$A:$A,J$39,Summary!$AR:$AR,"<>Pending",Summary!$AS:$AS,"<>Open",Summary!$AT:$AT,$B44) -> 0 | ... T44: =COUNTIFS(Summary!$A:$A,T$39,Summary!$AR:$AR,"<>Pending",Summary!$AS:$AS,"<>Open",Summary!$AT:$AT,$B44) -> 0 | U44: =SUM(C44:T44) -> 0
A45: Total | C45: =SUM(C40:C44) -> 0 | D45: =SUM(D40:D44) -> 0 | E45: =SUM(E40:E44) -> 0 | F45: =SUM(F40:F44) -> 0 | G45: =SUM(G40:G44) -> 0 | H45: =SUM(H40:H44) -> 0 | I45: =SUM(I40:I44) -> 0 | J45: =SUM(J40:J44) -> 0 | ... T45: =SUM(T40:T44) -> 0 | U45: =SUM(C45:T45) -> 0
...

Sheet Summary
A2: Claims Tracker (Contractor's Claims) | BE2: Pre-TIA Report (CM / Claims Team) | BI2: TIA Assessment (Planning Team)
A3: RSG-CM-FRM-0018 | AS3: Pending Action with: | BF3: - 1 to 25 days | BJ3: - 1 to 7 days
AS4: Contractor | AT4: {=SUMPRODUCT(SUBTOTAL(3,OFFSET($AT$16:$AT$194,ROW($AT$16:$AT$194)-ROW($AT$16),0,1)),--($AT$16:$AT$194=$AS4))} -> 24 | BF4: - 26 to 50 days | BJ4: - 8 to 14 days
B5: Program No.: | C5: Programs 1 - 16 | E5: Programs 1 - 16 | AS5: Engineer | AT5: {=SUMPRODUCT(SUBTOTAL(3,OFFSET($AT$16:$AT$194,ROW($AT$16:$AT$194)-ROW($AT$16),0,1)),--($AT$16:$AT$194=$AS5))} -> 0 | BF5: - 51 to 70 days | BJ5: - 15 to 21 days
B6: Program Name: | C6: AMAALA | E6: AMAALA | G6: =IF(Program_01!F6="Insert Entry Date for Newly Added Claims","Insert Entry Date for Newly Added Claims in Prog 01",IF([1]Program_02!F6="Insert Entry Date for Newly Added Claims","Insert Entry Date for Newly Added Claims in Prog 02",IF([1]Program_03!F6="Insert Entry Date for Newly Added Claims,","Insert Entry Date for Newly Added Claims in Prog 03",IF([1]Program_04!F6="Insert Entry Date for Newly Added Claims","Insert Entry Date for Newly Added Claims in Prog 04",IF([1]Program_05!F6="Insert Entry Date for Newly Added Claims","Insert Entry Date for Newly Added Claims in Prog 05",IF([1]Program_06!F6="Insert Entry Date for Newly Added Claims","Insert Entry Date for Newly Added Claims in Prog 06",IF([1]Program_07!F6="Insert Entry Date for Newly Added Claims","Insert Entry Date for Newly Added Claims in Prog 07",IF([1]Program_08!F6="Insert Entry Date for Newly Added Claims","Insert Entry Date for Newly Added Claims in Prog 08",IF([1]Program_09!F6="Insert Entry Date for Newly Added Claims","Insert Entry Date for Newly Added Claims in Prog 09",IF([1]Program_10!F6="Insert Entry Date for Newly Added Claims","Insert Entry Date for Newly Added Claims in Prog 10",IF([1]Program_11!F6="Insert Entry Date for Newly Added Claims","Insert Entry Date for Newly Added Claims in Prog 11",IF([1]Program_12!F6="Insert Entry Date for Newly Added Claims","Insert Entry Date for Newly Added Claims in Prog 12",IF([1]Program_16!F6="Insert Entry Date for Newly Added Claims","Insert Entry Date for Newly Added Claims in Prog 16",""))))))))))))) | AS6: Commercial Team | AT6: {=SUMPRODUCT(SUBTOTAL(3,OFFSET($AT$16:$AT$194,ROW($AT$16:$AT$194)-ROW($AT$16),0,1)),--($AT$16:$AT$194=$AS6))} -> 33 | BF6: - exceeding 70 days | BJ6: - exceeding 21 days
B7: Claims Tracker as of: | C7: 46162 | E7: 45904 | W7: Claim Initial Response Letter: | AS7: Planning Team | AT7: {=SUMPRODUCT(SUBTOTAL(3,OFFSET($AT$16:$AT$194,ROW($AT$16:$AT$194)-ROW($AT$16),0,1)),--($AT$16:$AT$194=$AS7))} -> 9 | BM7: Assessment Report: | BP7: HLEAR Assessment Report: | BU7: DVO/VO/CA:
Y8: - 1 to 7 days | AS8: Claims Team | AT8: {=SUMPRODUCT(SUBTOTAL(3,OFFSET($AT$16:$AT$194,ROW($AT$16:$AT$194)-ROW($AT$16),0,1)),--($AT$16:$AT$194=$AS8))} -> 4 | BE8: Finalization of Report (CM / Claims Team) | BN8: - 1 to 45 days | BQ8: - 1 to 25 days | BV8: - 1 to 30 days
Y9: - 8 to 14 days | AS9: Legal Team | AT9: {=SUMPRODUCT(SUBTOTAL(3,OFFSET($AT$16:$AT$194,ROW($AT$16:$AT$194)-ROW($AT$16),0,1)),--($AT$16:$AT$194=$AS9))} -> 0 | BF9: - 1 to 3 days | BN9: - 46 to 90 days | BQ9: - 26 to 50 days | BV9: - 31 to 60 days
Y10: - 15 to 21 days | AS10: For Presentation to Management | AT10: {=SUMPRODUCT(SUBTOTAL(3,OFFSET($AT$16:$AT$194,ROW($AT$16:$AT$194)-ROW($AT$16),0,1)),--($AT$16:$AT$194=$AS10))} -> 0 | AV10: OPEN | AW10: OPEN | BF10: - 4 to 6 days | BN10: - 91 to 140 days | BQ10: - 51 to 75 days | BV10: - 61 to 90 days
Y11: - exceeding 21 days | AS11: Cost claim awaiting conclusion of EoT | AT11: {=SUMPRODUCT(SUBTOTAL(3,OFFSET($AT$16:$AT$194,ROW($AT$16:$AT$194)-ROW($AT$16),0,1)),--($AT$16:$AT$194=$AS11))} -> 0 | AV11: {=SUMPRODUCT(SUBTOTAL(3,OFFSET($AV$17:$AV$194,ROW($AV$17:$AV$194)-ROW($AV$17),0,1)),--($AV$17:$AV$194=$AV10))} -> 0 | AW11: {=SUMPRODUCT(SUBTOTAL(3,OFFSET($AW$17:$AW$194,ROW($AW$17:$AW$194)-ROW($AW$17),0,1)),--($AW$17:$AW$194=$AW10))} -> 83 | BF11: - 7 to 10 days | BN11: - exceeding 140 days | BQ11: - exceeding 75 days | BV11: - exceeding 90 days
AM12: Notice of Dissatisfaction | AO12: {=SUMPRODUCT(SUBTOTAL(3,OFFSET($AN$17:$AN$194,ROW($AN$17:$AN$194)-ROW($AN$17),0,1)),--($AN$17:$AN$194="Yes"))} -> 7 | AS12: Assessment in WF | AT12: {=SUMPRODUCT(SUBTOTAL(3,OFFSET($AT$16:$AT$194,ROW($AT$16:$AT$194)-ROW($AT$16),0,1)),--($AT$16:$AT$194=$AS12))} -> 3 | AV12: CLOSED | AW12: CLOSED | BF12: - exceeding 10 days
AM13: Notice of Dispute | AO13: {=SUMPRODUCT(SUBTOTAL(3,OFFSET($AO$17:$AO$194,ROW($AO$17:$AO$194)-ROW($AO$17),0,1)),--($AO$17:$AO$194="Yes"))} -> 4 | AS13: DVO/VO in WF | AT13: {=SUMPRODUCT(SUBTOTAL(3,OFFSET($AT$16:$AT$194,ROW($AT$16:$AT$194)-ROW($AT$16),0,1)),--($AT$16:$AT$194=$AS13))} -> 0 | AV13: {=SUMPRODUCT(SUBTOTAL(3,OFFSET($AV$17:$AV$194,ROW($AV$17:$AV$194)-ROW($AV$17),0,1)),--($AV$17:$AV$194=$AV12))} -> 9 | AW13: {=SUMPRODUCT(SUBTOTAL(3,OFFSET($AW$17:$AW$194,ROW($AW$17:$AW$194)-ROW($AW$17),0,1)),--($AW$17:$AW$194=$AW12))} -> 70
BD14: CM / Claims Team | BF14: Planning Team | BH14: CM / Claims Team
A15: Details | J15: Claim Type | Q15: Claim Submitted by the Contractor | U15: 21 calendar days from Date of First Submission | Y15: Period of Consultation with Contractor re particulars, etc. (Period Varies) | AA15: Employer's Assessment (should be 30 calendar days from Date of Fully Detailed Claim) | AF15: Clause 3.5 | AJ15: DVO/VO /Contract Amendment | AM15: Rejected on Merit or Revise & Resubmit | AN15: Notice of Dissatisfaction Yes or No | AO15: Notice of Dispute Yes or No | AR15: Claim Status / Action / Remarks | AV15: Open Claims as of | AW15: Claims From | AY15: Contractor Claim / RSG Assessment / DVO | BC15: Claims Intermediate KPIs | BK15: 140 Days KPI (EOT or Cost Assessment Report Issued to Contractor) | BT15: 90 Days KPI (DVO/VO/CA Issued to Contractor) | CA15: =COUNTIF(CA18:CA194,"Y") -> 50 | CB15: =COUNTIF(CB18:CB194,"Y") -> 7 | CG15: =SUBTOTAL(9,CG17:CG194) -> 1.6353672e+08 | CH15: =SUBTOTAL(9,CH17:CH194) -> 25901926
A16: Program | B16: Item | C16: Assessment Type | D16: Contract No. | E16: Asset Code | F16: Project Name | G16: Scope | H16: Contractor Name | I16: Claim Type | J16: EOT | K16: Prolongation | L16: Disruption | M16: Acceleration | N16: NOD | O16: Other Claims | Q16: Claim Title | R16: Contractor's Claim (Reference) | S16: Contractor's Claim Submission (Date) | U16: RSG Initial Response (Reference) | V16: RSG Initial Response (Date) | W16: Period between Contractor's Submission & Engineer / Employer's Initial Response | Y16: Last Action Date / Type of Discussion [letters, workshops, emails, meetings, etc.] | AA16: Fully Detailed Claim (FDC) Submitted by Contractor (Reference) | AB16: Contractor's FDC Submission (Date) | AC16: Employer's FDC Response / Assessment Report (Reference) | AD16: Employer's FDC Response (Date) | AF16: Agree (Reference) | AG16: Agree (Date) | AH16: Determination (Reference) | AI16: Determination (Date) | AJ16: DVO/VO/CA (Reference) | AK16: DVO/VO/CA (Date) | AQ16: Discretionary EOT | AR16: Status 1 | AS16: Status 2 | AT16: Action | AU16: Remarks | AV16: 45291 | AW16: 45292 | AY16: Contractor's FDC Submission (Date) | AZ16: RSG Assessment Report (Date) | BA16: DVO/VO/ CA (Date) | BC16: EAR / HLEAR Start Date | BD16: EAR / HLEAR Pre-TIA (No. of Days and Date) | BF16: EAR / HLEAR TIA Assessment (No. of Days and Date) | BH16: EAR / HLEAR / COST EAR Finalization (No. of Days and Date) | BK16: KPI Report Closure Month (MM-YY) | BL16: Discretionary EOT Closure Month (MM-YY) | BM16: 140 days from Contractor's Claim FDC submission to DEOT issued | BN16: Days from Contractor's Claim FDC submission | BO16: Days taken for Final Claims Closed | BP16: Total Claims Closed | BQ16: Days taken for Final Claims Under Process > 140 days | BR16: Days taken for Final Claims Under Process > 140 days | BT16: KPI Report Closure Month (MM-YY) | BU16: 90 days from Assessment Report | BV16: Days taken for Final Claims Closed | BW16: Total Claims Closed | BX16: Days taken for Final Claims Under Process > 90 days | BY16: Total Claims Under Process > 90 days | CA16: Report Issued? | CB16: DVO/VO/CA Issued? | CC16: Date of Entry in the Tracker | CG16: Cost Claimd by the Contractor | CH16: AMAALA Assessment | CI16: Status A
A18: PROGRAM 01
A19: Program_01 | B19: 1 | C19: =IFERROR(INDEX(Program_01!$B:$B,MATCH($B19,Program_01!$A:$A,0)),"") -> FULL TIA EAR | D19: =IFERROR(INDEX(Program_01!D:D,MATCH($B19,Program_01!A:A,0)),"") -> 1TB01003C14 | E19: =IFERROR(INDEX(Program_01!$E:$E,MATCH($B19,Program_01!$A:$A,0)),"") -> 1.TB.01.003.01 | F19: =IFERROR(INDEX(Program_01!$F:$F,MATCH($B19,Program_01!$A:$A,0)),"") -> AMAALA Yacht Club | G19: =IFERROR(INDEX(Program_01!$G:$G,MATCH($B19,Program_01!$A:$A,0)),"") -> Triple Bay Piling - Beach, RSMLI, Yacht Club and Marina Village Precinct (Hotel 1 and 2) | H19: =IFERROR(INDEX(Program_01!$H:$H,MATCH($B19,Program_01!$A:$A,0)),"") -> NSCC International Saudi Contracting | I19: =IFERROR(IF($D19="","",INDEX($J$16:$O$16,MATCH(1,J19:O19,0))),"") -> EOT | J19: =IFERROR(INDEX(Program_01!$I:$I,MATCH($B19,Program_01!$A:$A,0)),"") -> 1 | K19: =IFERROR(INDEX(Program_01!$J:$J,MATCH($B19,Program_01!$A:$A,0)),"") -> 0 | L19: =IFERROR(INDEX(Program_01!$K:$K,MATCH($B19,Program_01!$A:$A,0)),"") -> 0 | M19: =IFERROR(INDEX(Program_01!$L:$L,MATCH($B19,Program_01!$A:$A,0)),"") -> 0 | N19: =IFERROR(INDEX(Program_01!$L:$L,MATCH($B19,Program_01!$A:$A,0)),"") -> 0 | O19: =IFERROR(INDEX(Program_01!$N:$N,MATCH($B19,Program_01!$A:$A,0)),"") -> 0 | Q19: =IFERROR(INDEX(Program_01!$C:$C,MATCH($B19,Program_01!$A:$A,0)),"") -> NSCC Consolidated Claim - All Plots (Time) | R19: =IFERROR(INDEX(Program_01!$V:$V,MATCH($B19,Program_01!$A:$A,0)),"") -> TB04400-005C13-NSC-LTR-0326 | S19: =IFERROR(INDEX(Program_01!$W:$W,MATCH($B19,Program_01!$A:$A,0)),"") -> 45045 | U19: =IFERROR(INDEX(Program_01!$Z:$Z,MATCH($B19,Program_01!$A:$A,0)),"") -> Not responded | V19: =IFERROR(INDEX(Program_01!$AA:$AA,MATCH($B19,Program_01!$A:$A,0)),"") -> N/A | W19: =IF(OR($S19="",$V19="N/A"),"",IF(AND($S19<>0,$V19=0),TODAY()-$S19,IF(AND($S19<>"",$V19<>""),$V19-$S19))) | Y19: =IFERROR(INDEX(Program_01!$BD:$BD,MATCH($B19,Program_01!$A:$A,0)),"") -> 0 | AA19: =IFERROR(IF((INDEX(Program_01!$AD:$AD,MATCH($B19,Program_01!$A:$A,0))=""),INDEX(Program_01!$V:$V,MATCH($B19,Program_01!$A:$A,0)),INDEX(Program_01!$AD:$AD,MATCH($B19,Program_01!$A:$A,0))),"") -> 1TB04400-005C13-NSC-LTR-0395 | AB19: =IFERROR(IF((INDEX(Program_01!$AE:$AE,MATCH($B19,Program_01!$A:$A,0))=""),INDEX(Program_01!$W:$W,MATCH($B19,Program_01!$A:$A,0)),INDEX(Program_01!$AE:$AE,MATCH($B19,Program_01!$A:$A,0))),"") -> 45241 | AC19: =IFERROR(IF($I19="EOT",INDEX(Program_01!$AN:$AN,MATCH($B19,Program_01!$A:$A,0)),INDEX(Program_01!$AY:$AY,MATCH($B19,Program_01!$A:$A,0))),"") -> TB04400-031D03-WSP-LTR-0138 | AD19: =IFERROR(IF($I19="EOT",INDEX(Program_01!$AO:$AO,MATCH($B19,Program_01!$A:$A,0)),INDEX(Program_01!$AZ:$AZ,MATCH($B19,Program_01!$A:$A,0))),"") -> 45243 | AH19: =IF(OR($D19="",$AS19="VO Issued",$AS19="Open"),"",IF(OR($AC19="Rejected",$AC19="Superseded",$AC19="Dealt Separately"),$AC19,IF($I19="EOT",INDEX(Program_01!$AR:$AR,MATCH($B19,Program_01!$A:$A,0)),INDEX(Program_01!$BB:$BB,MATCH($B19,Program_01!$A:$A,0))))) -> TB04400-031D03-WSP-LTR-0138 | AI19: =IF(OR($A19="",$B19="",$I19="",$AS19="VO Issued",$AS19="Open"),"",IF(OR($AD19="N/A"),$AD19,IF($I19="EOT",INDEX(Program_01!$AS:$AS,MATCH($B19,Program_01!$A:$A,0)),INDEX(Program_01!$BC:$BC,MATCH($B19,Program_01!$A:$A,0))))) -> 45243 | AJ19: =IF(OR($D19="",$I19="",$AS19="Determination Issued",$AS19="Rejected",$AS19="Open"),"",IF(OR($AH19="Rejected",$AH19="Dealt Separately",$AH19="Superseded",$AH19="Withdrawn"),"N/A",IF($I19="EOT",INDEX(Program_01!AR:AR,MATCH($B19,Program_01!A:A,0)),INDEX(Program_01!BB:BB,MATCH($B19,Program_01!A:A,0))))) | AK19: =IF(OR($A19="",$B19="",$I19="",$AS19="Determination Issued",$AS19="Rejected",$AS19="Open"),"",IF($AJ19="N/A","N/A",IF($I19="EOT",INDEX(Program_01!AS:AS,MATCH($B19,Program_01!A:A,0)),INDEX(Program_01!BC:BC,MATCH($B19,Program_01!A:A,0))))) | AM19: =IFERROR(INDEX(Program_01!$BT:$BT,MATCH($B19,Program_01!$A:$A,0)),"") -> 0 | AN19: =IFERROR(INDEX(Program_01!$BU:$BU,MATCH($B19,Program_01!$A:$A,0)),"") -> 0 | AO19: =IFERROR(INDEX(Program_01!$BV:$BV,MATCH($B19,Program_01!$A:$A,0)),"") -> 0 | AP19: =IF(OR($AN19="Yes",$AO19="Yes"),"1","") | AQ19: =IFERROR(INDEX(Program_01!$BN:$BN,MATCH($B19,Program_01!$A:$A,0)),"") -> 0 | AR19: =IFERROR(INDEX(Program_01!$BO:$BO,MATCH($B19,Program_01!$A:$A,0)),"") -> Assessment Report Issued | AS19: =IFERROR(INDEX(Program_01!$BP:$BP,MATCH($B19,Program_01!$A:$A,0)),"") -> Determination Issued | AT19: =IFERROR(INDEX(Program_01!$BQ:$BQ,MATCH($B19,Program_01!$A:$A,0)),"") -> Closed | AU19: =IFERROR(INDEX(Program_01!$BR:$BR,MATCH($B19,Program_01!$A:$A,0)),"") -> Assessment and determination issued on 13 Nov 23. | AV19: =IF($I19="","",IF($S19>$AV$16,"",IF($AS19="OPEN","OPEN",IF($AS19="","",IF(AND($AS19<>"OPEN",$AT19="CLOSED"),"CLOSED",IF(AND($AS19<>"OPEN",$AT19<>"CLOSED"),"OPEN","")))))) -> CLOSED | AW19: =IF($I19="","",IF($S19<$AW$16,"",IF($AS19="OPEN","OPEN",IF($AS19="","",IF(AND($AS19<>"OPEN",$AT19="CLOSED"),"CLOSED",IF(AND($AS19<>"OPEN",$AT19<>"CLOSED"),"OPEN","")))))) | AX19: =IF(OR($AV19="OPEN",$AV19="CLOSED"),$AV19,$AW19) -> CLOSED | AY19: =IF(C19="HLEAR",BC19,AB19) -> 45241 | AZ19: =IF($AD19=0,"",AD19) -> 45243 | BA19: =IF(AND($AI19="",$AK19=""),"",IF($AI19="",$AK19,$AI19)) -> 45243 | BC19: =IFERROR(INDEX(Program_01!BF:BF,MATCH($B19,Program_01!$A:$A,0)),"") -> 45241 | BD19: =IFERROR(INDEX(Program_01!BG:BG,MATCH($B19,Program_01!$A:$A,0)),"") -> N/A | BE19: =IFERROR(INDEX(Program_01!BH:BH,MATCH($B19,Program_01!$A:$A,0)),"") -> 0 | BF19: =IFERROR(INDEX(Program_01!BI:BI,MATCH($B19,Program_01!$A:$A,0)),"") -> 0 | BG19: =IFERROR(INDEX(Program_01!BJ:BJ,MATCH($B19,Program_01!$A:$A,0)),"") -> 0 | BH19: =IFERROR(INDEX(Program_01!BK:BK,MATCH($B19,Program_01!$A:$A,0)),"") -> 0 | BI19: =IFERROR(INDEX(Program_01!BL:BL,MATCH($B19,Program_01!$A:$A,0)),"") -> 0 | BK19: =IFERROR(IF(INDEX(Program_01!$BX:$BX,MATCH($B19,Program_01!$A:$A,0))=DATE(1900,1,0),"",INDEX(Program_01!$BX:$BX,MATCH($B19,Program_01!$A:$A,0))),"") -> 45260 | BL19: =IFERROR(IF(INDEX(Program_01!$BY:$BY,MATCH($B19,Program_01!$A:$A,0))=DATE(1900,1,0),"",INDEX(Program_01!$BY:$BY,MATCH($B19,Program_01!$A:$A,0))),"") | BM19: =IF(OR($AZ19="",$AZ19="N/A"),"",IF(AND($AZ19="",$AY19<>""),TODAY()-$AY19,$AZ19-$AY19)) -> 2 | BN19: =IF(OR($C19="DEOT",$C19="N/A",$I19=""),"",IF(OR($AM19="Revise & resubmit",$AT19="Awaiting Conclusion of EoT",$AR19="Not Applicable",$AY19=0,$AY19="TBA",$AZ19="N/A",AY19=0),0,IF(AND($AR19="Assessment Report Issued",$AT19<>""),$AZ19-$AY19,IF(AND($AR19="Pending",$AT19="Contractor"),"",IF(AND($AZ19="",$AY19<>""),TODAY()-$AY19,$AZ19-$AY19))))) -> 2 | BO19: =IF(OR($AR19<>"ASSESSMENT REPORT ISSUED"),"",IF($BN19<>"",$BN19,"")) -> 2 | BP19: =IF($AR19="ASSESSMENT REPORT ISSUED","1",IF(AND($AT19="Closed",$AR19<>"Pending"),"1","")) -> 1 | BQ19: =IF(AND($AR19="Pending",$BN19>140),$BN19,"") | BR19: =IF(BQ19="","","1") | BT19: =IFERROR(IF(INDEX(Program_01!$BZ:$BZ,MATCH($B19,Program_01!$A:$A,0))=DATE(1900,1,0),"",INDEX(Program_01!$BZ:$BZ,MATCH($B19,Program_01!$A:$A,0))),"") | BU19: =IF(OR($I19="",$AV19="",$AM19<>0,$BA19="N/A",$AZ19=""),"",IF(AND($BA19="",$AZ19<>""),TODAY()-$AZ19,$BA19-$AZ19)) -> 0 | BV19: =IF(OR($AS19="Determination Issued",$AS19="VO Issued"),$BU19,"") -> 0 | BW19: =IF(OR($AT19="CLOSED",$AS19="Determination Issued",$AS19="VO Issued"),"1","") -> 1 | BX19: =IF(OR($AS19="Determination Issued",$AS19="VO Issued",$AS19="Rejected",$AS19="Canceled",$AS19="Superseded",$AS19="Not Applicable",$BU19=""),"",IF($BU19>90,$BU19,"")) | BY19: =IF(BX19="","","1") | CA19: =IF($I19="","",IF(AND($AR19="Assessment Report Issued",$AZ19<>""),"Y","N")) -> Y | CB19: =IF($I19="","",IF(OR($AS19="Determination Issued",$AS19="VO Issued"),"Y","N")) -> Y | CC19: =IFERROR(INDEX(Program_01!$CE:$CE,MATCH($B19,Program_01!$A:$A,0)),"") -> 0 | CD19: =MAX(S19,CC19) -> 45045 | CG19: =IFERROR(INDEX(Program_01!$AT:$AT,MATCH($B19,Program_01!$A:$A,0)),"") -> 0 | CH19: =IFERROR(INDEX(Program_01!$AX:$AX,MATCH($B19,Program_01!$A:$A,0)),"") -> 0
A20: Program_01 | B20: 2 | C20: =IFERROR(INDEX(Program_01!$B:$B,MATCH($B20,Program_01!$A:$A,0)),"") -> COST EAR | D20: =IFERROR(INDEX(Program_01!$D:$D,MATCH($B20,Program_01!$A:$A,0)),"") -> 1TB01003C14 | E20: =IFERROR(INDEX(Program_01!$E:$E,MATCH($B20,Program_01!$A:$A,0)),"") -> 1.TB.01.003.01 | F20: =IFERROR(INDEX(Program_01!$F:$F,MATCH($B20,Program_01!$A:$A,0)),"") -> AMAALA Yacht Club | G20: =IFERROR(INDEX(Program_01!$G:$G,MATCH($B20,Program_01!$A:$A,0)),"") -> Triple Bay Piling - Beach, RSMLI, Yacht Club and Marina Village Precinct (Hotel 1 and 2) | H20: =IFERROR(INDEX(Program_01!$H:$H,MATCH($B20,Program_01!$A:$A,0)),"") -> NSCC International Saudi Contracting | I20: =IFERROR(IF($D20="","",INDEX($J$16:$O$16,MATCH(1,J20:O20,0))),"") -> Prolongation | J20: =IFERROR(INDEX(Program_01!$I:$I,MATCH($B20,Program_01!$A:$A,0)),"") -> 0 | K20: =IFERROR(INDEX(Program_01!$J:$J,MATCH($B20,Program_01!$A:$A,0)),"") -> 1 | L20: =IFERROR(INDEX(Program_01!$K:$K,MATCH($B20,Program_01!$A:$A,0)),"") -> 0 | M20: =IFERROR(INDEX(Program_01!$L:$L,MATCH($B20,Program_01!$A:$A,0)),"") -> 0 | N20: =IFERROR(INDEX(Program_01!$L:$L,MATCH($B20,Program_01!$A:$A,0)),"") -> 0 | O20: =IFERROR(INDEX(Program_01!$N:$N,MATCH($B20,Program_01!$A:$A,0)),"") -> 0 | Q20: =IFERROR(INDEX(Program_01!$C:$C,MATCH($B20,Program_01!$A:$A,0)),"") -> NSCC Consolidated Claim - All Plots (Cost) | R20: =IFERROR(INDEX(Program_01!$V:$V,MATCH($B20,Program_01!$A:$A,0)),"") -> 1TB04400-005C13-NSC-LTR-0326 | S20: =IFERROR(INDEX(Program_01!$W:$W,MATCH($B20,Program_01!$A:$A,0)),"") -> 45045 | U20: =IFERROR(INDEX(Program_01!$Z:$Z,MATCH($B20,Program_01!$A:$A,0)),"") -> Not responded | V20: =IFERROR(INDEX(Program_01!$AA:$AA,MATCH($B20,Program_01!$A:$A,0)),"") -> N/A | W20: =IF(OR($S20="",$V20="N/A"),"",IF(AND($S20<>0,$V20=0),TODAY()-$S20,IF(AND($S20<>"",$V20<>""),$V20-$S20))) | Y20: =IFERROR(INDEX(Program_01!$BD:$BD,MATCH($B20,Program_01!$A:$A,0)),"") -> 1TB04400-005C13-NSC-LTR-0326 dated 29 Apr 23 1TB04400-005C13-NSC-LTR-0386 dated 09 Oct 23 1TB04400-005C13-NSC-LTR-0393 dated 28 Oct 23 1TB04400-005C13-NSC-LTR-0395 dated 01 Nov 23 1TB04400-005C13-NSC-LTR-0400 dated 20 Feb 24 1TB04400-400000-WSP-LTR-0002 dated 26 Feb 24 requesting HO overhead particulars. 1TB04400-005C13-NSC-LTR-0401 dated 26 Feb 24 submission of requested documents. 1TB04400-005C13-NSC-LTR-0403 dated 04 Jul 24 | AA20: =IFERROR(IF((INDEX(Program_01!$AD:$AD,MATCH($B20,Program_01!$A:$A,0))=""),INDEX(Program_01!$V:$V,MATCH($B20,Program_01!$A:$A,0)),INDEX(Program_01!$AD:$AD,MATCH($B20,Program_01!$A:$A,0))),"") -> 1TB04400-005C13-NSC-LTR-0395 dated 11 Nov 23 1TB04400-005C13-NSC-LTR-0401 dated 26 Feb 24 1TB04400-005C13-NSC-LTR-0403 04 Jul 24 RFA Signoff | AB20: =IFERROR(IF((INDEX(Program_01!$AE:$AE,MATCH($B20,Program_01!$A:$A,0))=""),INDEX(Program_01!$W:$W,MATCH($B20,Program_01!$A:$A,0)),INDEX(Program_01!$AE:$AE,MATCH($B20,Program_01!$A:$A,0))),"") -> 45509 | AC20: =IFERROR(IF($I20="EOT",INDEX(Program_01!$AN:$AN,MATCH($B20,Program_01!$A:$A,0)),INDEX(Program_01!$AY:$AY,MATCH($B20,Program_01!$A:$A,0))),"") -> 1TB04400-400000-AMA-LTR-0056 | AD20: =IFERROR(IF($I20="EOT",INDEX(Program_01!$AO:$AO,MATCH($B20,Program_01!$A:$A,0)),INDEX(Program_01!$AZ:$AZ,MATCH($B20,Program_01!$A:$A,0))),"") -> 45578 | AH20: =IF(OR($D20="",$AS20="VO Issued",$AS20="Open"),"",IF(OR($AC20="Rejected",$AC20="Superseded",$AC20="Dealt Separately"),$AC20,IF($I20="EOT",INDEX(Program_01!$AR:$AR,MATCH($B20,Program_01!$A:$A,0)),INDEX(Program_01!$BB:$BB,MATCH($B20,Program_01!$A:$A,0))))) -> 1TB04400-400000-AMA-DVO-CM-0002 - DVO 013 | AI20: =IF(OR($A20="",$B20="",$I20="",$AS20="VO Issued",$AS20="Open"),"",IF(OR($AD20="N/A"),$AD20,IF($I20="EOT",INDEX(Program_01!$AS:$AS,MATCH($B20,Program_01!$A:$A,0)),INDEX(Program_01!$BC:$BC,MATCH($B20,Program_01!$A:$A,0))))) -> 45585 | AJ20: =IF(OR($D20="",$I20="",$AS20="Determination Issued",$AS20="Rejected",$AS20="Open"),"",IF(OR($AH20="Rejected",$AH20="Dealt Separately",$AH20="Superseded",$AH20="Withdrawn"),"N/A",IF($I20="EOT",INDEX(Program_01!AR:AR,MATCH($B20,Program_01!A:A,0)),INDEX(Program_01!BB:BB,MATCH($B20,Program_01!A:A,0))))) -> 1TB04400-400000-AMA-DVO-CM-0002 - DVO 013 | AK20: =IF(OR($A20="",$B20="",$I20="",$AS20="Determination Issued",$AS20="Rejected",$AS20="Open"),"",IF($AJ20="N/A","N/A",IF($I20="EOT",INDEX(Program_01!AS:AS,MATCH($B20,Program_01!A:A,0)),INDEX(Program_01!BC:BC,MATCH($B20,Program_01!A:A,0))))) -> 45585 | AM20: =IFERROR(INDEX(Program_01!$BT:$BT,MATCH($B20,Program_01!$A:$A,0)),"") -> 0 | AN20: =IFERROR(INDEX(Program_01!$BU:$BU,MATCH($B20,Program_01!$A:$A,0)),"") -> 0 | AO20: =IFERROR(INDEX(Program_01!$BV:$BV,MATCH($B20,Program_01!$A:$A,0)),"") -> 0 | AP20: =IF(OR($AN20="Yes",$AO20="Yes"),"1","") | AQ20: =IFERROR(INDEX(Program_01!$BN:$BN,MATCH($B20,Program_01!$A:$A,0)),"") -> 0 | AR20: =IFERROR(INDEX(Program_01!$BO:$BO,MATCH($B20,Program_01!$A:$A,0)),"") -> Assessment Report Issued | AS20: =IFERROR(INDEX(Program_01!$BP:$BP,MATCH($B20,Program_01!$A:$A,0)),"") -> DVO Issued | AT20: =IFERROR(INDEX(Program_01!$BQ:$BQ,MATCH($B20,Program_01!$A:$A,0)),"") -> Closed | AU20: =IFERROR(INDEX(Program_01!$BR:$BR,MATCH($B20,Program_01!$A:$A,0)),"") -> 29 Jul 24: Commercial leads and senior managment meeting with NSCC to close out final account 12 August 2024 : Final Account Settlment RFA currently in progress, once approved the commercial claims report will be updated to make reference to the approved RFA and submitted for approval. 26 Aug 24: No update available (Blake on Leave) 8 Sep 2024 - Commercial report is currently in WF for approval reflecting the approved RFA final settlement amount RFA 1TB04400-400000-AMA-RFA-CM-0004 dated 5 Aug 24 24 Sep 24: Assessment report in WF-004674 07 Oct 24: Assessment report approved by GCEO. However, it will not be issued to the contractor. as the EoT Costs contained within, form part of the previously agreed and GCEO signed off final account settlement of SAR 108,561,603. a DVO for the Final account settlemetent under preperation. commercial to prepare teh cover letter & issue it to the contractor ASAP 13 Oct 24: Report issued to NSCC via letter ref 1TB04400-400000-AMA-LTR-0056 14 Oct 24: NSCC issued the acceptance letter, Commercial to issue the final account DVO 09 Oct 24: DVO issued to contractor. 10 Oct 24: DVO signed by the contractor NOTE: RFA for Final Account Settlment Signed off and therefore this item is now considered closed | AV20: =IF($I20="","",IF($S20>$AV$16,"",IF($AS20="OPEN","OPEN",IF($AS20="","",IF(AND($AS20<>"OPEN",$AT20="CLOSED"),"CLOSED",IF(AND($AS20<>"OPEN",$AT20<>"CLOSED"),"OPEN","")))))) -> CLOSED | AW20: =IF($I20="","",IF($S20<$AW$16,"",IF($AS20="OPEN","OPEN",IF($AS20="","",IF(AND($AS20<>"OPEN",$AT20="CLOSED"),"CLOSED",IF(AND($AS20<>"OPEN",$AT20<>"CLOSED"),"OPEN","")))))) | AX20: =IF(OR($AV20="OPEN",$AV20="CLOSED"),$AV20,$AW20) -> CLOSED | AY20: =IF(C20="HLEAR",BC20,AB20) -> 45509 | AZ20: =IF($AD20=0,"",AD20) -> 45578 | BA20: =IF(AND($AI20="",$AK20=""),"",IF($AI20="",$AK20,$AI20)) -> 45585 | BC20: =IFERROR(INDEX(Program_01!BF:BF,MATCH($B20,Program_01!$A:$A,0)),"") -> 45509 | BD20: =IFERROR(INDEX(Program_01!BG:BG,MATCH($B20,Program_01!$A:$A,0)),"") -> N/A | BE20: =IFERROR(INDEX(Program_01!BH:BH,MATCH($B20,Program_01!$A:$A,0)),"") -> 0 | BF20: =IFERROR(INDEX(Program_01!BI:BI,MATCH($B20,Program_01!$A:$A,0)),"") -> N/A | BG20: =IFERROR(INDEX(Program_01!BJ:BJ,MATCH($B20,Program_01!$A:$A,0)),"") -> 0 | BH20: =IFERROR(INDEX(Program_01!BK:BK,MATCH($B20,Program_01!$A:$A,0)),"") -> 0 | BI20: =IFERROR(INDEX(Program_01!BL:BL,MATCH($B20,Program_01!$A:$A,0)),"") -> 0 | BK20: =IFERROR(IF(INDEX(Program_01!$BX:$BX,MATCH($B20,Program_01!$A:$A,0))=DATE(1900,1,0),"",INDEX(Program_01!$BX:$BX,MATCH($B20,Program_01!$A:$A,0))),"") -> 45578 | BL20: =IFERROR(IF(INDEX(Program_01!$BY:$BY,MATCH($B20,Program_01!$A:$A,0))=DATE(1900,1,0),"",INDEX(Program_01!$BY:$BY,MATCH($B20,Program_01!$A:$A,0))),"") | BM20: =IF(OR($AZ20="",$AZ20="N/A"),"",IF(AND($AZ20="",$AY20<>""),TODAY()-$AY20,$AZ20-$AY20)) -> 69 | BN20: =IF(OR($C20="DEOT",$C20="N/A",$I20=""),"",IF(OR($AM20="Revise & resubmit",$AT20="Awaiting Conclusion of EoT",$AR20="Not Applicable",$AY20=0,$AY20="TBA",$AZ20="N/A",AY20=0),0,IF(AND($AR20="Assessment Report Issued",$AT20<>""),$AZ20-$AY20,IF(AND($AR20="Pending",$AT20="Contractor"),"",IF(AND($AZ20="",$AY20<>""),TODAY()-$AY20,$AZ20-$AY20))))) -> 69 | BO20: =IF(OR($AR20<>"ASSESSMENT REPORT ISSUED"),"",IF($BN20<>"",$BN20,"")) -> 69 | BP20: =IF($AR20="ASSESSMENT REPORT ISSUED","1",IF(AND($AT20="Closed",$AR20<>"Pending"),"1","")) -> 1 | BQ20: =IF(AND($AR20="Pending",$BN20>140),$BN20,"") | BR20: =IF(BQ20="","","1") | BT20: =IFERROR(IF(INDEX(Program_01!$BZ:$BZ,MATCH($B20,Program_01!$A:$A,0))=DATE(1900,1,0),"",INDEX(Program_01!$BZ:$BZ,MATCH($B20,Program_01!$A:$A,0))),"") -> 45585 | BU20: =IF(OR($I20="",$AV20="",$AM20<>0,$BA20="N/A",$AZ20=""),"",IF(AND($BA20="",$AZ20<>""),TODAY()-$AZ20,$BA20-$AZ20)) -> 7 | BV20: =IF(OR($AS20="Determination Issued",$AS20="VO Issued"),$BU20,"") | BW20: =IF(OR($AT20="CLOSED",$AS20="Determination Issued",$AS20="VO Issued"),"1","") -> 1 | BX20: =IF(OR($AS20="Determination Issued",$AS20="VO Issued",$AS20="Rejected",$AS20="Canceled",$AS20="Superseded",$AS20="Not Applicable",$BU20=""),"",IF($BU20>90,$BU20,"")) | BY20: =IF(BX20="","","1") | CA20: =IF($I20="","",IF(AND($AR20="Assessment Report Issued",$AZ20<>""),"Y","N")) -> Y | CB20: =IF($I20="","",IF(OR($AS20="Determination Issued",$AS20="VO Issued"),"Y","N")) -> N | CC20: =IFERROR(INDEX(Program_01!$CE:$CE,MATCH($B20,Program_01!$A:$A,0)),"") -> 0 | CD20: =MAX(S20,CC20) -> 45045 | CG20: =IFERROR(INDEX(Program_01!$AT:$AT,MATCH($B20,Program_01!$A:$A,0)),"") -> 653085.79 | CH20: =IFERROR(INDEX(Program_01!$AX:$AX,MATCH($B20,Program_01!$A:$A,0)),"") -> 10071304 | CI20: Assessment Report Issued
